Workbook
Name SlicerCache_Table_2_Col_1: #N/A
Name SlicerCache_Table_2_Col_2: #N/A
Name SlicerCache_Table_2_Col_3: #N/A
Name SlicerCache_Table_2_Col_4: #N/A
Name SlicerCache_Table_2_Col_5: #N/A
Name SlicerCache_Table_4_Col_1: #N/A
Name SlicerCache_Table_4_Col_3: #N/A
Name SlicerCache_Table_6_Col_1: #N/A
Name SlicerCache_Table_6_Col_3: #N/A
Name SlicerCache_Table_8_Col_1: #N/A
Name SlicerCache_Table_8_Col_3: #N/A
Name SlicerCache_Table_9_Col_1: #N/A
Name SlicerCache_Table_9_Col_2: #N/A
Name SlicerCache_Table_9_Col_3: #N/A
Name SlicerCache_Table_11_Col_1: #N/A
Name SlicerCache_Table_11_Col_2: #N/A
Name SlicerCache_Table_11_Col_3: #N/A
Name SlicerCache_Table_11_Col_4: #N/A
Name SlicerCache_Table_11_Col_5: #N/A
Name 切片器_变动情况: #REF!
Name 切片器_单位: #REF!
Name 切片器_单位5: #REF!
Name 切片器_评审阶段: #REF!
Name 切片器_评审阶段3: #REF!
Name 切片器_设计阶段: #REF!
Name 切片器_设计阶段1: #REF!
Name 切片器_设计阶段10: #REF!
Name 切片器_设计阶段2: #REF!
Name 切片器_设计阶段3: #REF!
Name 切片器_设计阶段4: #REF!
Name 切片器_设计阶段5: #REF!
Name 切片器_设计阶段6: #REF!
Name 切片器_设计阶段8: #REF!
Name 切片器_时间: #REF!
Name 切片器_时间2: #REF!
Name 切片器_时间5: #REF!
Name 切片器_统计模式: #REF!
Name 切片器_统计模式11: #REF!
Name 切片器_统计模式3: #REF!
Name 切片器_统计模式6: #REF!
Name 切片器_统计模式7: #REF!
Name 切片器_统计模式8: #REF!
Name 切片器_统计模式9: #REF!
Name 切片器_统计维度: #REF!
Name 切片器_统计维度4: #REF!
Name 切片器_统计项目: #REF!
Name 切片器_统计项目6: #REF!

Sheet 2025数据
A1: 主网项目评审明细表（2025年）
A2: 项目名称 | B2: 设计单位 | C2: 可研评审时间 | D2: 可研发文时间 | E2: 是否完成可研审查 | F2: 可研评审时长 | G2: 可研调整评审时间 | H2: 可研调整发文时间 | I2: 是否完成可研调整审查 | J2: 可研成调整评审时长 | K2: 初设评审时间 | L2: 初设发文时间 | M2: 是否完成初设审查 | N2: 初设评审时长 | O2: 初设调整评审时间 | P2: 初设调整发文时间 | Q2: 是否完成初设调整审查 | R2: 初设调整评审时长 | S2: 施工图评审时间 | T2: 施工图发文时间 | U2: 是否完成施工图审查 | V2: 施工图预算评审时长 | W2: 施工图预算调整评审时间 | X2: 施工图预算调整发文时间 | Y2: 是否完成预算调整审查 | Z2: 施工图预算调整评审时长 | AA2: 重大设计变更评审时间 | AB2: 重大设计变更发文时间 | AC2: 是否完成重大设计变更审查 | AD2: 设计变更评审时长 | AE2: 负责人 | AF2: 变电 | AG2: 线路 | AH2: 可研估算送审动态投资 | AI2: 可研估算审定动态投资 | AJ2: 可研估算送审静态投资 | AK2: 可研估算审定静态投资 | AL2: 可研估算校正（静态） | AM2: 审定-送审（动态）可研估算 | AN2: 审定-送审（静态）可研估算 | AO2: 估算调整送审动态投资 | AP2: 估算调整审定动态投资 | AQ2: 估算调整送审静态投资 | AR2: 估算调整审定静态投资 | AS2: 可研调整估算校正 | AT2: 审定-送审（静态）调整估算 | AU2: 初设概算送审动态投资 | AV2: 初设概算审定动态投资 | AW2: 初设概算送审静态投资 | AX2: 初设概算审定静态投资 | AY2: 初设概算校正 | AZ2: 审定-送审（静态）初设概算 | BA2: 概算-估算（动态） | BB2: 概算调整送审动态投资 | BC2: 概算调整审定动态投资 | BD2: 概算调整送审静态投资 | BE2: 概算调整审定静态投资 | BF2: 初设调整概算校正 | BG2: 审定-送审（静态）概算调整 | BH2: 施工图预算送审动态投资 | BI2: 施工图预算审定动态投资 | BJ2: 施工图预算送审静态投资 | BK2: 施工图预算审定静态投资 | BL2: 施工图预算校正 | BM2: 审定-送审（静态）施工图预算 | BN2: 预算-概算（动态） | BO2: 预算调整预算送审动态投资 | BP2: 预算调整预算审定动态投资 | BQ2: 预算调整预算送审静态投资 | BR2: 预算调整预算审定静态投资 | BS2: 施工图调整预算校正 | BT2: 审定-送审（静态）预算调整 | BU2: 重大设计变更送审动态投资 | BV2: 重大设计变更审定动态投资 | BW2: 重大设计变更送审静态投资 | BX2: 重大设计变更审定静态投资 | BY2: 重大设计变更校正 | BZ2: 审定-送审（静态）重大变更 | CB2: 非工作日
A3: 110kV田美（食品）输变电工程（电气分册） | B3: 汇隽院 | C3: 46052 | E3: =IF(C3<>0,IF(D3<>0,"0","1"),"") -> 1 | F3: =IF(E3="0",NETWORKDAYS(C3,D3,$CB$3:$CB$19),NETWORKDAYS(C3,'2025整理'!$S$1,$CB$3:$CB$19)) -> -25 | J3: =IF(I3="0",NETWORKDAYS(G3,H3,$EO$3:$EO$11),"") | N3: =IF(M3="0",NETWORKDAYS(K3,L3,$EO$3:$EO$11),"") | R3: =IF(Q3="0",NETWORKDAYS(O3,P3,$EO$3:$EO$10),"") | V3: =IF(U3="0",NETWORKDAYS(S3,T3,$EO$3:$EO$11),"") | Z3: =IF(Y3="0",NETWORKDAYS(W3,X3,$EO$3:$EO$11),"") | AD3: =IF(AC3="0",NETWORKDAYS(AA3,AB3,$EO$3:$EO$11),"") | AE3: 谢瑞莲 | AF3: 谢瑞莲 | AG3: 王志会 | CB3: 45658
A4: 110kV榕村站扩建第三台主变工程 | B4: 工程院 | C4: 46052 | E4: =IF(C4<>0,IF(D4<>0,"0","1"),"") -> 1 | F4: =IF(E4="0",NETWORKDAYS(C4,D4,$CB$3:$CB$19),NETWORKDAYS(C4,'2025整理'!$S$1,$CB$3:$CB$19)) -> -25 | J4: =IF(I4="0",NETWORKDAYS(G4,H4,$EO$3:$EO$11),"") | N4: =IF(M4="0",NETWORKDAYS(K4,L4,$EO$3:$EO$11),"") | R4: =IF(Q4="0",NETWORKDAYS(O4,P4,$EO$3:$EO$10),"") | V4: =IF(U4="0",NETWORKDAYS(S4,T4,$EO$3:$EO$11),"") | Z4: =IF(Y4="0",NETWORKDAYS(W4,X4,$EO$3:$EO$11),"") | AD4: =IF(AC4="0",NETWORKDAYS(AA4,AB4,$EO$3:$EO$11),"") | AE4: 樊心田 | AF4: 樊心田 | AG4: 黄小珈 | CB4: 45685
A5: 110kV茶东站扩建主变工程 | B5: 汇隽院 | E5: =IF(C5<>0,IF(D5<>0,"0","1"),"") | J5: =IF(I5="0",NETWORKDAYS(G5,H5,$EO$3:$EO$11),"") | K5: 45946 | L5: 45958 | M5: =IF(K5<>0,IF(L5<>0,"0","1"),"") -> 0 | N5: =IF(M5="0",NETWORKDAYS(K5,L5,$CB$3:$CB$19),NETWORKDAYS(K5,'2025整理'!$S$1,$CB$3:$CB$19)) -> 9 | R5: =IF(Q5="0",NETWORKDAYS(O5,P5,$EO$3:$EO$10),"") | U5: =IF(S5<>0,IF(T5<>0,"0","1"),"") | V5: =IF(U5="0",NETWORKDAYS(S5,T5,$EO$3:$EO$11),"") | Z5: =IF(Y5="0",NETWORKDAYS(W5,X5,$EO$3:$EO$11),"") | AD5: =IF(AC5="0",NETWORKDAYS(AA5,AB5,$EO$3:$EO$11),"") | AE5: 樊心田 | AF5: 樊心田 | AG5: 王志会 | AI5: 4391.23 | AK5: 4330.65 | AL5: =IF(AND(AK5<>"",AJ5<>""),IF(AK5>AJ5,"核增",IF(AK5<AJ5,"核减","不变")),"") | AM5: =IF(AND(AI5<>"",AH5<>""),MAX(ABS(AI5),ABS(AH5))-MIN(ABS(AI5),ABS(AH5)),"") | AN5: =IF(AND(AK5<>"",AJ5<>""),MAX(ABS(AK5),ABS(AJ5))-MIN(ABS(AK5),ABS(AJ5)),"") | AS5: =IF(AND(AR5<>"",AQ5<>""),IF(AR5>AQ5,"核增",IF(AR5<AQ5,"核减","不变")),"") | AT5: =IF(AND(AR5<>"",AQ5<>""),MAX(ABS(AR5),ABS(AQ5))-MIN(ABS(AR5),ABS(AQ5)),"") | AU5: 4350.28 | AV5: 4262.34 | AW5: 4296.61 | AX5: 4210.08 | AY5: =IF(AND(AX5<>"",AW5<>""),IF(AX5>AW5,"核增",IF(AX5<AW5,"核减","不变")),"") -> 核减 | AZ5: =IF(AND(AX5<>"",AW5<>""),MAX(ABS(AX5),ABS(AW5))-MIN(ABS(AX5),ABS(AW5)),"") -> 86.53 | BA5: =IF(AND(AV5<>"",AI5<>""),IF(AV5>AI5,"核增",IF(AV5<AI5,"核减","不变")),"")&TEXT(IF(AND(AV5<>"",AI5<>""),MAX(ABS(AV5),ABS(AI5))-MIN(ABS(AV5),ABS(AI5)),""),"0.00") -> 核减128.89 | BF5: =IF(AND(BE5<>"",BD5<>""),IF(BE5>BD5,"核增",IF(BE5<BD5,"核减","不变")),"") | BL5: =IF(AND(BK5<>"",BJ5<>""),IF(BK5>BJ5,"核增",IF(BK5<BJ5,"核减","不变")),"") | BM5: =IF(AND(BK5<>"",BJ5<>""),MAX(ABS(BK5),ABS(BJ5))-MIN(ABS(BK5),ABS(BJ5)),"") | BN5: =IF(AND(BI5<>"",AV5<>""),IF(BI5>AV5,"核增",IF(BI5<AV5,"核减","不变")),"")&TEXT(IF(AND(BI5<>"",AV5<>""),MAX(ABS(BI5),ABS(AV5))-MIN(ABS(BI5),ABS(AV5)),""),"0.00") | BS5: =IF(AND(BR5<>"",BQ5<>""),IF(BR5>BQ5,"核增",IF(BR5<BQ5,"核减","不变")),"") | BT5: =IF(AND(BR5<>"",BQ5<>""),MAX(ABS(BR5),ABS(BQ5))-MIN(ABS(BR5),ABS(BQ5)),"") | BY5: =IF(AND(BX5<>"",BW5<>""),IF(BX5>BW5,"核增",IF(BX5<BW5,"核减","不变")),"") | BZ5: =IF(AND(BX5<>"",BW5<>""),MAX(ABS(BX5),ABS(BW5))-MIN(ABS(BX5),ABS(BW5)),"") | CB5: 45686
A6: 110kV富城输变电工程（土建分册） | B6: 工程院 | C6: 46052 | E6: =IF(C6<>0,IF(D6<>0,"0","1"),"") -> 1 | F6: =IF(E6="0",NETWORKDAYS(C6,D6,$CB$3:$CB$19),NETWORKDAYS(C6,'2025整理'!$S$1,$CB$3:$CB$19)) -> -25 | J6: =IF(I6="0",NETWORKDAYS(G6,H6,$EO$3:$EO$11),"") | N6: =IF(M6="0",NETWORKDAYS(K6,L6,$EO$3:$EO$11),"") | R6: =IF(Q6="0",NETWORKDAYS(O6,P6,$EO$3:$EO$10),"") | V6: =IF(U6="0",NETWORKDAYS(S6,T6,$EO$3:$EO$11),"") | Z6: =IF(Y6="0",NETWORKDAYS(W6,X6,$EO$3:$EO$11),"") | AD6: =IF(AC6="0",NETWORKDAYS(AA6,AB6,$EO$3:$EO$11),"") | AE6: 方明 | AF6: 方明 | AG6: - | BZ6: =IF(AND(BX6<>"",BW6<>""),MAX(ABS(BX6),ABS(BW6))-MIN(ABS(BX6),ABS(BW6)),"") | CB6: 45326
A7: 110 kV运东输变电工程土建分册 | B7: 广州院 | C7: 46052 | E7: =IF(C7<>0,IF(D7<>0,"0","1"),"") -> 1 | F7: =IF(E7="0",NETWORKDAYS(C7,D7,$CB$3:$CB$19),NETWORKDAYS(C7,'2025整理'!$S$1,$CB$3:$CB$19)) -> -25 | J7: =IF(I7="0",NETWORKDAYS(G7,H7,$EO$3:$EO$11),"") | N7: =IF(M7="0",NETWORKDAYS(K7,L7,$EO$3:$EO$11),"") | R7: =IF(Q7="0",NETWORKDAYS(O7,P7,$EO$3:$EO$10),"") | V7: =IF(U7="0",NETWORKDAYS(S7,T7,$EO$3:$EO$11),"") | Z7: =IF(Y7="0",NETWORKDAYS(W7,X7,$EO$3:$EO$11),"") | AD7: =IF(AC7="0",NETWORKDAYS(AA7,AB7,$EO$3:$EO$11),"") | AE7: 谢瑞莲 | AF7: 谢瑞莲 | AG7: - | CB7: 45751
A8: 110 kV上岭输变电工程 | B8: 广州院 | C8: 45860 | D8: 45877 | E8: =IF(C8<>0,IF(D8<>0,"0","1"),"") -> 0 | F8: =IF(E8="0",NETWORKDAYS(C8,D8,$CB$3:$CB$19),NETWORKDAYS(C8,'2025整理'!$S$1,$CB$3:$CB$19)) -> 14 | J8: =IF(I8="0",NETWORKDAYS(G8,H8,$EO$3:$EO$11),"") | N8: =IF(M8="0",NETWORKDAYS(K8,L8,$EO$3:$EO$11),"") | R8: =IF(Q8="0",NETWORKDAYS(O8,P8,$EO$3:$EO$10),"") | V8: =IF(U8="0",NETWORKDAYS(S8,T8,$EO$3:$EO$11),"") | Z8: =IF(Y8="0",NETWORKDAYS(W8,X8,$EO$3:$EO$11),"") | AD8: =IF(AC8="0",NETWORKDAYS(AA8,AB8,$EO$3:$EO$11),"") | AE8: 樊心田 | AF8: 樊心田 | AG8: 黄小珈 | AH8: 20862.51 | AI8: 20321.91 | AJ8: 20546.22 | AK8: 20321.91 | AL8: =IF(AND(AK8<>"",AJ8<>""),IF(AK8>AJ8,"核增",IF(AK8<AJ8,"核减","不变")),"") -> 核减 | AM8: =IF(AND(AI8<>"",AH8<>""),MAX(ABS(AI8),ABS(AH8))-MIN(ABS(AI8),ABS(AH8)),"") -> 540.6 | AN8: =IF(AND(AK8<>"",AJ8<>""),MAX(ABS(AK8),ABS(AJ8))-MIN(ABS(AK8),ABS(AJ8)),"") -> 224.31 | BZ8: =IF(AND(BX8<>"",BW8<>""),MAX(ABS(BX8),ABS(BW8))-MIN(ABS(BX8),ABS(BW8)),"") | CB8: 45413
A9: 海珠站配套220kV线路工程 | B9: 省院 | C9: 45630 | D9: 45707 | E9: =IF(C9<>0,IF(D9<>0,"0","1"),"") -> 0 | F9: =IF(E9="0",NETWORKDAYS(C9,D9,$CB$3:$CB$19),NETWORKDAYS(C9,'2025整理'!$S$1,$CB$3:$CB$19)) -> 53 | J9: =IF(I9="0",NETWORKDAYS(G9,H9,$EO$3:$EO$11),"") | K9: 45818 | L9: 45833 | M9: =IF(K9<>0,IF(L9<>0,"0","1"),"") -> 0 | N9: =IF(M9="0",NETWORKDAYS(K9,L9,$CB$3:$CB$19),NETWORKDAYS(K9,'2025整理'!$S$1,$CB$3:$CB$19)) -> 12 | R9: =IF(Q9="0",NETWORKDAYS(O9,P9,$EO$3:$EO$10),"") | S9: 45947 | U9: =IF(S9<>0,IF(T9<>0,"0","1"),"") -> 1 | V9: =IF(U9="0",NETWORKDAYS(S9,T9,$CB$3:$CB$19),NETWORKDAYS(S9,'2025整理'!$S$1,$CB$3:$CB$19)) -> 52 | Z9: =IF(Y9="0",NETWORKDAYS(W9,X9,$EO$3:$EO$11),"") | AD9: =IF(AC9="0",NETWORKDAYS(AA9,AB9,$EO$3:$EO$11),"") | AE9: 陈伟哲 | AF9: 方明 | AG9: 陈伟哲 | AH9: 90456.44 | AI9: 87097.32 | AJ9: 89277.88 | AK9: 85932 | AL9: =IF(AND(AK9<>"",AJ9<>""),IF(AK9>AJ9,"核增",IF(AK9<AJ9,"核减","不变")),"") -> 核减 | AM9: =IF(AND(AI9<>"",AH9<>""),MAX(ABS(AI9),ABS(AH9))-MIN(ABS(AI9),ABS(AH9)),"") -> 3359.12 | AN9: =IF(AND(AK9<>"",AJ9<>""),MAX(ABS(AK9),ABS(AJ9))-MIN(ABS(AK9),ABS(AJ9)),"") -> 3345.88 | AU9: 86798.67 | AV9: 85076.17 | AW9: 85651.38 | AX9: 84017.04 | AY9: =IF(AND(AX9<>"",AW9<>""),IF(AX9>AW9,"核增",IF(AX9<AW9,"核减","不变")),"") -> 核减 | AZ9: =IF(AND(AX9<>"",AW9<>""),MAX(ABS(AX9),ABS(AW9))-MIN(ABS(AX9),ABS(AW9)),"") -> 1634.34 | BA9: =IF(AND(AV9<>"",AI9<>""),IF(AV9>AI9,"核增",IF(AV9<AI9,"核减","不变")),"")&TEXT(IF(AND(AV9<>"",AI9<>""),MAX(ABS(AV9),ABS(AI9))-MIN(ABS(AV9),ABS(AI9)),""),"0.00") -> 核减2021.15 | CB9: 45414
A10: 广州海珠站配套 220 kV线路工程（附属用房部分） | B10: 省院 | C10: 46052 | E10: =IF(C10<>0,IF(D10<>0,"0","1"),"") -> 1 | F10: =IF(E10="0",NETWORKDAYS(C10,D10,$CB$3:$CB$19),NETWORKDAYS(C10,'2025整理'!$S$1,$CB$3:$CB$19)) -> -25 | J10: =IF(I10="0",NETWORKDAYS(G10,H10,$EO$3:$EO$11),"") | AE10: 方明 | AF10: 方明 | AG10: - | CB10: 45417
A11: 500kV傍海（番南）站配套220kV线路工程（第一分册） | B11: 广州院 | C11: 45637 | D11: 45684 | E11: =IF(C11<>0,IF(D11<>0,"0","1"),"") -> 0 | F11: =IF(E11="0",NETWORKDAYS(C11,D11,$EO$3:$EO$11),"") -> 34 | J11: =IF(I11="0",NETWORKDAYS(G11,H11,$EO$3:$EO$11),"") | K11: 45761 | L11: 45771 | M11: =IF(K11<>0,IF(L11<>0,"0","1"),"") -> 0 | N11: =IF(M11="0",NETWORKDAYS(K11,L11,$EO$3:$EO$11),"") -> 9 | R11: =IF(Q11="0",NETWORKDAYS(O11,P11,$EO$3:$EO$10),"") | S11: 45996 | U11: =IF(S11<>0,IF(T11<>0,"0","1"),"") -> 1 | V11: =IF(U11="0",NETWORKDAYS(S11,T11,$CB$3:$CB$19),NETWORKDAYS(S11,'2025整理'!$S$1,$CB$3:$CB$19)) -> 17 | Z11: =IF(Y11="0",NETWORKDAYS(W11,X11,$EO$3:$EO$11),"") | AD11: =IF(AC11="0",NETWORKDAYS(AA11,AB11,$EO$3:$EO$11),"") | AE11: 王志会 | AF11: 樊心田 | AG11: 王志会 | AH11: 30592.25 | AI11: 27459.26 | AJ11: 30038.73 | AK11: 26963.87 | AL11: =IF(AND(AK11<>"",AJ11<>""),IF(AK11>AJ11,"核增",IF(AK11<AJ11,"核减","不变")),"") -> 核减 | AM11: =IF(AND(AI11<>"",AH11<>""),MAX(ABS(AI11),ABS(AH11))-MIN(ABS(AI11),ABS(AH11)),"") -> 3132.99 | AN11: =IF(AND(AK11<>"",AJ11<>""),MAX(ABS(AK11),ABS(AJ11))-MIN(ABS(AK11),ABS(AJ11)),"") -> 3074.86 | AU11: 26452.38 | AV11: 26587.08 | AW11: 26022.32 | AX11: 26155.17 | AY11: =IF(AND(AX11<>"",AW11<>""),IF(AX11>AW11,"核增",IF(AX11<AW11,"核减","不变")),"") -> 核增 | AZ11: =IF(AND(AX11<>"",AW11<>""),MAX(ABS(AX11),ABS(AW11))-MIN(ABS(AX11),ABS(AW11)),"") -> 132.85 | BA11: =IF(AND(AV11<>"",AI11<>""),IF(AV11>AI11,"核增",IF(AV11<AI11,"核减","不变")),"")&TEXT(IF(AND(AV11<>"",AI11<>""),MAX(ABS(AV11),ABS(AI11))-MIN(ABS(AV11),ABS(AI11)),""),"0.00") -> 核减872.18 | CB11: 45445
A12: 220kV花地站配合牵引站接入工程 | B12: 广州院 | C12: 45649 | D12: 45663 | E12: =IF(C12<>0,IF(D12<>0,"0","1"),"") -> 0 | F12: =IF(E12="0",NETWORKDAYS(C12,D12,$CB$3:$CB$19),"") -> 10 | J12: =IF(I12="0",NETWORKDAYS(G12,H12,$EO$3:$EO$11),"") | K12: 45673 | L12: 45680 | M12: =IF(K12<>0,IF(L12<>0,"0","1"),"") -> 0 | N12: =IF(M12="0",NETWORKDAYS(K12,L12,$EO$3:$EO$11),"") -> 6 | S12: 45727 | T12: 45740 | U12: =IF(S12<>0,IF(T12<>0,"0","1"),"") -> 0 | V12: =IF(U12="0",NETWORKDAYS(S12,T12,$CB$3:$CB$19),"") -> 10 | AE12: 谢瑞莲 | AF12: 谢瑞莲 | AG12: - | AH12: 843 | AI12: 645.18 | AJ12: 843 | AK12: 645.18 | AL12: =IF(AND(AK12<>"",AJ12<>""),IF(AK12>AJ12,"核增",IF(AK12<AJ12,"核减","不变")),"") -> 核减 | AM12: =IF(AND(AI12<>"",AH12<>""),MAX(ABS(AI12),ABS(AH12))-MIN(ABS(AI12),ABS(AH12)),"") -> 197.82 | AN12: =IF(AND(AK12<>"",AJ12<>""),MAX(ABS(AK12),ABS(AJ12))-MIN(ABS(AK12),ABS(AJ12)),"") -> 197.82 | AU12: 628.3 | AV12: 620.69 | AW12: 628.3 | AX12: 620.69 | AY12: =IF(AND(AX12<>"",AW12<>""),IF(AX12>AW12,"核增",IF(AX12<AW12,"核减","不变")),"") -> 核减 | AZ12: =IF(AND(AX12<>"",AW12<>""),MAX(ABS(AX12),ABS(AW12))-MIN(ABS(AX12),ABS(AW12)),"") -> 7.61 | BA12: =IF(AND(AV12<>"",AI12<>""),IF(AV12>AI12,"核增",IF(AV12<AI12,"核减","不变")),"")&TEXT(IF(AND(AV12<>"",AI12<>""),MAX(ABS(AV12),ABS(AI12))-MIN(ABS(AV12),ABS(AI12)),""),"0.00") -> 核减24.49 | BH12: 551.29 | BI12: 580.52 | BJ12: 551.29 | BK12: 580.52 | BL12: =IF(AND(BK12<>"",BJ12<>""),IF(BK12>BJ12,"核增",IF(BK12<BJ12,"核减","不变")),"") -> 核增 | BM12: =IF(AND(BK12<>"",BJ12<>""),MAX(ABS(BK12),ABS(BJ12))-MIN(ABS(BK12),ABS(BJ12)),"") -> 29.23 | BN12: =IF(AND(BI12<>"",AV12<>""),IF(BI12>AV12,"核增",IF(BI12<AV12,"核减","不变")),"")&TEXT(IF(AND(BI12<>"",AV12<>""),MAX(ABS(BI12),ABS(AV12))-MIN(ABS(BI12),ABS(AV12)),""),"0.00") -> 核减40.17 | CB12: 45566
A13: 220kV昌岗站第三台主变扩工程 | B13: 广州院 | C13: 45825 | D13: 45856 | E13: =IF(C13<>0,IF(D13<>0,"0","1"),"") -> 0 | F13: =IF(E13="0",NETWORKDAYS(C13,D13,$CB$3:$CB$19),NETWORKDAYS(C13,'2025整理'!$S$1,$CB$3:$CB$19)) -> 24 | J13: =IF(I13="0",NETWORKDAYS(G13,H13,$EO$3:$EO$11),"") | K13: 45986 | M13: =IF(K13<>0,IF(L13<>0,"0","1"),"") -> 1 | N13: =IF(M13="0",NETWORKDAYS(K13,L13,$CB$3:$CB$19),NETWORKDAYS(K13,'2025整理'!$S$1,$CB$3:$CB$19)) -> 25 | AE13: 谢瑞莲 | AF13: 谢瑞莲 | AG13: 黄小珈 | AH13: 14512.85 | AI13: 14344.24 | AJ13: 14379.14 | AK13: 14212.04 | AL13: =IF(AND(AK13<>"",AJ13<>""),IF(AK13>AJ13,"核增",IF(AK13<AJ13,"核减","不变")),"") -> 核减 | AM13: =IF(AND(AI13<>"",AH13<>""),MAX(ABS(AI13),ABS(AH13))-MIN(ABS(AI13),ABS(AH13)),"") -> 168.61 | AN13: =IF(AND(AK13<>"",AJ13<>""),MAX(ABS(AK13),ABS(AJ13))-MIN(ABS(AK13),ABS(AJ13)),"") -> 167.1 | AY13: =IF(AND(AX13<>"",AW13<>""),IF(AX13>AW13,"核增",IF(AX13<AW13,"核减","不变")),"") | CB13: 45567
A14: 110kV太平扩建第三台主变工程 | B14: 工程院 | C14: 45701 | D14: 45721 | E14: =IF(C14<>0,IF(D14<>0,"0","1"),"") -> 0 | F14: =IF(E14="0",NETWORKDAYS(C14,D14,$EO$3:$EO$11),"") -> 15 | J14: =IF(I14="0",NETWORKDAYS(G14,H14,$EO$3:$EO$11),"") | K14: 45854 | L14: 45874 | M14: =IF(K14<>0,IF(L14<>0,"0","1"),"") -> 0 | N14: =IF(M14="0",NETWORKDAYS(K14,L14,$CB$3:$CB$19),NETWORKDAYS(K14,'2025整理'!$S$1,$CB$3:$CB$19)) -> 15 | S14: 45923 | T14: 45947 | U14: =IF(S14<>0,IF(T14<>0,"0","1"),"") -> 0 | V14: =IF(U14="0",NETWORKDAYS(S14,T14,$CB$3:$CB$19),NETWORKDAYS(S14,'2025整理'!$S$1,$CB$3:$CB$19)) -> 19 | AE14: 方明 | AF14: 方明 | AG14: 黄小珈 | AH14: 2018.73 | AI14: 2041.22 | AJ14: 1999.91 | AK14: 2022.24 | AL14: =IF(AND(AK14<>"",AJ14<>""),IF(AK14>AJ14,"核增",IF(AK14<AJ14,"核减","不变")),"") -> 核增 | AM14: =IF(AND(AI14<>"",AH14<>""),MAX(ABS(AI14),ABS(AH14))-MIN(ABS(AI14),ABS(AH14)),"") -> 22.49 | AN14: =IF(AND(AK14<>"",AJ14<>""),MAX(ABS(AK14),ABS(AJ14))-MIN(ABS(AK14),ABS(AJ14)),"") -> 22.33 | AU14: 2019.05 | AV14: 2016.71 | AW14: 2000.26 | AX14: 1999.59 | AY14: =IF(AND(AX14<>"",AW14<>""),IF(AX14>AW14,"核增",IF(AX14<AW14,"核减","不变")),"") -> 核减 | AZ14: =IF(AND(AX14<>"",AW14<>""),MAX(ABS(AX14),ABS(AW14))-MIN(ABS(AX14),ABS(AW14)),"") -> 0.67 | BA14: =IF(AND(AV14<>"",AI14<>""),IF(AV14>AI14,"核增",IF(AV14<AI14,"核减","不变")),"")&TEXT(IF(AND(AV14<>"",AI14<>""),MAX(ABS(AV14),ABS(AI14))-MIN(ABS(AV14),ABS(AI14)),""),"0.00") -> 核减24.51 | BH14: 2037.17 | BI14: 2013.59 | BJ14: 2018.33 | BK14: 1995.05 | BL14: =IF(AND(BK14<>"",BJ14<>""),IF(BK14>BJ14,"核增",IF(BK14<BJ14,"核减","不变")),"") -> 核减 | BM14: =IF(AND(BK14<>"",BJ14<>""),MAX(ABS(BK14),ABS(BJ14))-MIN(ABS(BK14),ABS(BJ14)),"") -> 23.28 | BN14: =IF(AND(BI14<>"",AV14<>""),IF(BI14>AV14,"核增",IF(BI14<AV14,"核减","不变")),"")&TEXT(IF(AND(BI14<>"",AV14<>""),MAX(ABS(BI14),ABS(AV14))-MIN(ABS(BI14),ABS(AV14)),""),"0.00") -> 核减3.12 | CB14: 45568
A15: 220kV白鹅潭输变电工程（第一分册） | B15: 广州院 | C15: 45659 | D15: 45683 | E15: =IF(C15<>0,IF(D15<>0,"0","1"),"") -> 0 | F15: =IF(E15="0",NETWORKDAYS(C15,D15,$EO$3:$EO$11),"") -> 17 | J15: =IF(I15="0",NETWORKDAYS(G15,H15,$EO$3:$EO$11),"") | K15: 45813 | L15: 45831 | M15: =IF(K15<>0,IF(L15<>0,"0","1"),"") -> 0 | N15: =IF(M15="0",NETWORKDAYS(K15,L15,$CB$3:$CB$19),NETWORKDAYS(K15,'2025整理'!$S$1,$CB$3:$CB$19)) -> 13 | S15: 45876 | T15: 45922 | U15: =IF(S15<>0,IF(T15<>0,"0","1"),"") -> 0 | V15: =IF(U15="0",NETWORKDAYS(S15,T15,$CB$3:$CB$19),NETWORKDAYS(S15,'2025整理'!$S$1,$CB$3:$CB$19)) -> 33 | AE15: 陈伟哲 | AF15: 樊心田 | AG15: 陈伟哲 | AH15: 49674.46 | AI15: 44792.46 | AJ15: 48777.76 | AK15: 44304.37 | AL15: =IF(AND(AK15<>"",AJ15<>""),IF(AK15>AJ15,"核增",IF(AK15<AJ15,"核减","不变")),"") -> 核减 | AM15: =IF(AND(AI15<>"",AH15<>""),MAX(ABS(AI15),ABS(AH15))-MIN(ABS(AI15),ABS(AH15)),"") -> 4882 | AN15: =IF(AND(AK15<>"",AJ15<>""),MAX(ABS(AK15),ABS(AJ15))-MIN(ABS(AK15),ABS(AJ15)),"") -> 4473.39 | AU15: 44820.5 | AV15: 44748.66 | AW15: 44219.65 | AX15: 44204.12 | AY15: =IF(AND(AX15<>"",AW15<>""),IF(AX15>AW15,"核增",IF(AX15<AW15,"核减","不变")),"") -> 核减 | AZ15: =IF(AND(AX15<>"",AW15<>""),MAX(ABS(AX15),ABS(AW15))-MIN(ABS(AX15),ABS(AW15)),"") -> 15.53 | BA15: =IF(AND(AV15<>"",AI15<>""),IF(AV15>AI15,"核增",IF(AV15<AI15,"核减","不变")),"")&TEXT(IF(AND(AV15<>"",AI15<>""),MAX(ABS(AV15),ABS(AI15))-MIN(ABS(AV15),ABS(AI15)),""),"0.00") -> 核减43.80 | BH15: 46385.17 | BI15: 44734.03 | BJ15: 45820.71 | BK15: 44204.96 | BL15: =IF(AND(BK15<>"",BJ15<>""),IF(BK15>BJ15,"核增",IF(BK15<BJ15,"核减","不变")),"") -> 核减 | BM15: =IF(AND(BK15<>"",BJ15<>""),MAX(ABS(BK15),ABS(BJ15))-MIN(ABS(BK15),ABS(BJ15)),"") -> 1615.75 | BN15: =IF(AND(BI15<>"",AV15<>""),IF(BI15>AV15,"核增",IF(BI15<AV15,"核减","不变")),"")&TEXT(IF(AND(BI15<>"",AV15<>""),MAX(ABS(BI15),ABS(AV15))-MIN(ABS(BI15),ABS(AV15)),""),"0.00") -> 核减14.63 | CB15: 45571
A16: 110kV凫洲至保税线路工程 | B16: 广州院 | C16: 45660 | D16: 45673 | E16: =IF(C16<>0,IF(D16<>0,"0","1"),"") -> 0 | F16: =IF(E16="0",NETWORKDAYS(C16,D16,$CB$3:$CB$19),"") -> 10 | J16: =IF(I16="0",NETWORKDAYS(G16,H16,$EO$3:$EO$11),"") | K16: 45889 | L16: 45924 | M16: =IF(K16<>0,IF(L16<>0,"0","1"),"") -> 0 | N16: =IF(M16="0",NETWORKDAYS(K16,L16,$CB$3:$CB$19),NETWORKDAYS(K16,'2025整理'!$S$1,$CB$3:$CB$19)) -> 26 | R16: =IF(Q16="0",NETWORKDAYS(O16,P16,$EO$3:$EO$10),"") | V16: =IF(U16="0",NETWORKDAYS(S16,T16,$EO$3:$EO$11),"") | Z16: =IF(Y16="0",NETWORKDAYS(W16,X16,$EO$3:$EO$11),"") | AD16: =IF(AC16="0",NETWORKDAYS(AA16,AB16,$EO$3:$EO$11),"") | AE16: 黄小珈 | AF16: 谢瑞莲 | AG16: 黄小珈 | AH16: 25586.81 | AI16: 12884.58 | AJ16: 25151.24 | AK16: 12667.91 | AL16: =IF(AND(AK16<>"",AJ16<>""),IF(AK16>AJ16,"核增",IF(AK16<AJ16,"核减","不变")),"") -> 核减 | AM16: =IF(AND(AI16<>"",AH16<>""),MAX(ABS(AI16),ABS(AH16))-MIN(ABS(AI16),ABS(AH16)),"") -> 12702.23 | AN16: =IF(AND(AK16<>"",AJ16<>""),MAX(ABS(AK16),ABS(AJ16))-MIN(ABS(AK16),ABS(AJ16)),"") -> 12483.33 | AU16: 12513.22 | AV16: 11704 | AW16: 12323.6 | AX16: 11527.04 | AY16: =IF(AND(AX16<>"",AW16<>""),IF(AX16>AW16,"核增",IF(AX16<AW16,"核减","不变")),"") -> 核减 | AZ16: =IF(AND(AX16<>"",AW16<>""),MAX(ABS(AX16),ABS(AW16))-MIN(ABS(AX16),ABS(AW16)),"") -> 796.56 | BA16: =IF(AND(AV16<>"",AI16<>""),IF(AV16>AI16,"核增",IF(AV16<AI16,"核减","不变")),"")&TEXT(IF(AND(AV16<>"",AI16<>""),MAX(ABS(AV16),ABS(AI16))-MIN(ABS(AV16),ABS(AI16)),""),"0.00") -> 核减1180.58 | BZ16: =IF(AND(BX16<>"",BW16<>""),MAX(ABS(BX16),ABS(BW16))-MIN(ABS(BX16),ABS(BW16)),"")
A17: 110 kV旗坊输变电工程 | B17: 广州院 | C17: 45757 | D17: 45793 | E17: =IF(C17<>0,IF(D17<>0,"0","1"),"") -> 0 | F17: =IF(E17="0",NETWORKDAYS(C17,D17,$CB$3:$CB$19),NETWORKDAYS(C17,'2025整理'!$S$1,$CB$3:$CB$19)) -> 27 | J17: =IF(I17="0",NETWORKDAYS(G17,H17,$EO$3:$EO$11),"") | K17: 45912 | L17: 45930 | M17: =IF(K17<>0,IF(L17<>0,"0","1"),"") -> 0 | N17: =IF(M17="0",NETWORKDAYS(K17,L17,$CB$3:$CB$19),NETWORKDAYS(K17,'2025整理'!$S$1,$CB$3:$CB$19)) -> 13 | AE17: 方明 | AF17: 方明 | AG17: 黄小珈 | AH17: 17481.27 | AI17: 17611.86 | AJ17: 17185.86 | AK17: 17310.24 | AL17: =IF(AND(AK17<>"",AJ17<>""),IF(AK17>AJ17,"核增",IF(AK17<AJ17,"核减","不变")),"") -> 核增 | AM17: =IF(AND(AI17<>"",AH17<>""),MAX(ABS(AI17),ABS(AH17))-MIN(ABS(AI17),ABS(AH17)),"") -> 130.59 | AN17: =IF(AND(AK17<>"",AJ17<>""),MAX(ABS(AK17),ABS(AJ17))-MIN(ABS(AK17),ABS(AJ17)),"") -> 124.38 | AU17: 17420.58 | AV17: 17262.65 | AW17: 17136.31 | AX17: 16996.08 | AY17: =IF(AND(AX17<>"",AW17<>""),IF(AX17>AW17,"核增",IF(AX17<AW17,"核减","不变")),"") -> 核减 | AZ17: =IF(AND(AX17<>"",AW17<>""),MAX(ABS(AX17),ABS(AW17))-MIN(ABS(AX17),ABS(AW17)),"") -> 140.23 | BA17: =IF(AND(AV17<>"",AI17<>""),IF(AV17>AI17,"核增",IF(AV17<AI17,"核减","不变")),"")&TEXT(IF(AND(AV17<>"",AI17<>""),MAX(ABS(AV17),ABS(AI17))-MIN(ABS(AV17),ABS(AI17)),""),"0.00") -> 核减349.21
A18: 110kV水南站扩建第三台主变工程 | B18: 工程院 | C18: 45922 | D18: 45964 | E18: =IF(C18<>0,IF(D18<>0,"0","1"),"") -> 0 | F18: =IF(E18="0",NETWORKDAYS(C18,D18,$CB$3:$CB$19),NETWORKDAYS(C18,'2025整理'!$S$1,$CB$3:$CB$19)) -> 31 | J18: =IF(I18="0",NETWORKDAYS(G18,H18,$EO$3:$EO$11),"") | AE18: 樊心田 | AF18: 樊心田 | AG18: 黄小珈 | AH18: 4505.52 | AI18: 4500.05 | AJ18: 4443.18 | AK18: 4437.72 | AL18: =IF(AND(AK18<>"",AJ18<>""),IF(AK18>AJ18,"核增",IF(AK18<AJ18,"核减","不变")),"") -> 核减 | AM18: =IF(AND(AI18<>"",AH18<>""),MAX(ABS(AI18),ABS(AH18))-MIN(ABS(AI18),ABS(AH18)),"") -> 5.47 | AN18: =IF(AND(AK18<>"",AJ18<>""),MAX(ABS(AK18),ABS(AJ18))-MIN(ABS(AK18),ABS(AJ18)),"") -> 5.46 | AY18: =IF(AND(AX18<>"",AW18<>""),IF(AX18>AW18,"核增",IF(AX18<AW18,"核减","不变")),"")
A19: 110kV志诚输变电工程（第一分册） | B19: 工程院 | C19: 45848 | D19: 45855 | E19: =IF(C19<>0,IF(D19<>0,"0","1"),"") -> 0 | F19: =IF(E19="0",NETWORKDAYS(C19,D19,$CB$3:$CB$19),NETWORKDAYS(C19,'2025整理'!$S$1,$CB$3:$CB$19)) -> 6 | K19: 45875 | L19: 45888 | M19: =IF(K19<>0,IF(L19<>0,"0","1"),"") -> 0 | N19: =IF(M19="0",NETWORKDAYS(K19,L19,$CB$3:$CB$19),NETWORKDAYS(K19,'2025整理'!$S$1,$CB$3:$CB$19)) -> 10 | S19: 45957 | T19: 45972 | U19: =IF(S19<>0,IF(T19<>0,"0","1"),"") -> 0 | V19: =IF(U19="0",NETWORKDAYS(S19,T19,$CB$3:$CB$19),NETWORKDAYS(S19,'2025整理'!$S$1,$CB$3:$CB$19)) -> 12 | AE19: 樊心田 | AF19: 樊心田 | AG19: 黄小珈 | AH19: 13054.92 | AI19: 12734.06 | AJ19: 12786.64 | AK19: 12558.05 | AL19: =IF(AND(AK19<>"",AJ19<>""),IF(AK19>AJ19,"核增",IF(AK19<AJ19,"核减","不变")),"") -> 核减 | AM19: =IF(AND(AI19<>"",AH19<>""),MAX(ABS(AI19),ABS(AH19))-MIN(ABS(AI19),ABS(AH19)),"") -> 320.86 | AN19: =IF(AND(AK19<>"",AJ19<>""),MAX(ABS(AK19),ABS(AJ19))-MIN(ABS(AK19),ABS(AJ19)),"") -> 228.59 | AU19: 12702.3 | AV19: 12325.75 | AW19: 12546.12 | AX19: 12173.3 | AY19: =IF(AND(AX19<>"",AW19<>""),IF(AX19>AW19,"核增",IF(AX19<AW19,"核减","不变")),"") -> 核减 | AZ19: =IF(AND(AX19<>"",AW19<>""),MAX(ABS(AX19),ABS(AW19))-MIN(ABS(AX19),ABS(AW19)),"") -> 372.82 | BA19: =IF(AND(AV19<>"",AI19<>""),IF(AV19>AI19,"核增",IF(AV19<AI19,"核减","不变")),"")&TEXT(IF(AND(AV19<>"",AI19<>""),MAX(ABS(AV19),ABS(AI19))-MIN(ABS(AV19),ABS(AI19)),""),"0.00") -> 核减408.31 | BH19: 12209.93 | BI19: 11920.83 | BJ19: 12026.95 | BK19: 11742.26 | BL19: =IF(AND(BK19<>"",BJ19<>""),IF(BK19>BJ19,"核增",IF(BK19<BJ19,"核减","不变")),"") -> 核减 | BM19: =IF(AND(BK19<>"",BJ19<>""),MAX(ABS(BK19),ABS(BJ19))-MIN(ABS(BK19),ABS(BJ19)),"") -> 284.69 | BN19: =IF(AND(BI19<>"",AV19<>""),IF(BI19>AV19,"核增",IF(BI19<AV19,"核减","不变")),"")&TEXT(IF(AND(BI19<>"",AV19<>""),MAX(ABS(BI19),ABS(AV19))-MIN(ABS(BI19),ABS(AV19)),""),"0.00") -> 核减404.92
A20: 110kV南方输变电工程（第二分册） | B20: 广州院 | C20: 45813 | D20: 45826 | E20: =IF(C20<>0,IF(D20<>0,"0","1"),"") -> 0 | F20: =IF(E20="0",NETWORKDAYS(C20,D20,$CB$3:$CB$19),NETWORKDAYS(C20,'2025整理'!$S$1,$CB$3:$CB$19)) -> 10 | K20: 45999 | L20: 46008 | M20: =IF(K20<>0,IF(L20<>0,"0","1"),"") -> 0 | N20: =IF(M20="0",NETWORKDAYS(K20,L20,$CB$3:$CB$19),NETWORKDAYS(K20,'2025整理'!$S$1,$CB$3:$CB$19)) -> 8 | AE20: 方明 | AF20: 方明 | AG20: 黄小珈 | AH20: 4515.31 | AI20: 4484.99 | AJ20: 4438.31 | AK20: 4408.51 | AL20: =IF(AND(AK20<>"",AJ20<>""),IF(AK20>AJ20,"核增",IF(AK20<AJ20,"核减","不变")),"") -> 核减 | AM20: =IF(AND(AI20<>"",AH20<>""),MAX(ABS(AI20),ABS(AH20))-MIN(ABS(AI20),ABS(AH20)),"") -> 30.32 | AN20: =IF(AND(AK20<>"",AJ20<>""),MAX(ABS(AK20),ABS(AJ20))-MIN(ABS(AK20),ABS(AJ20)),"") -> 29.8 | AU20: 4216.65 | AV20: 4133.18 | AW20: 4144.77 | AX20: 4062.73 | AY20: =IF(AND(AX20<>"",AW20<>""),IF(AX20>AW20,"核增",IF(AX20<AW20,"核减","不变")),"") -> 核减 | AZ20: =IF(AND(AX20<>"",AW20<>""),MAX(ABS(AX20),ABS(AW20))-MIN(ABS(AX20),ABS(AW20)),"") -> 82.04 | BA20: =IF(AND(AV20<>"",AI20<>""),IF(AV20>AI20,"核增",IF(AV20<AI20,"核减","不变")),"")&TEXT(IF(AND(AV20<>"",AI20<>""),MAX(ABS(AV20),ABS(AI20))-MIN(ABS(AV20),ABS(AI20)),""),"0.00") -> 核减351.81
A21: 220kV花地站扩建第三台主变工程（第一分册） | B21: 广州院 | C21: 45927 | D21: 45941 | E21: =IF(C21<>0,IF(D21<>0,"0","1"),"") -> 0 | F21: =IF(E21="0",NETWORKDAYS(C21,D21,$CB$3:$CB$19),NETWORKDAYS(C21,'2025整理'!$S$1,$CB$3:$CB$19)) -> 10 | J21: =IF(I21="0",NETWORKDAYS(G21,H21,$EO$3:$EO$11),"") | K21: 45968 | L21: 45978 | M21: =IF(K21<>0,IF(L21<>0,"0","1"),"") -> 0 | N21: =IF(M21="0",NETWORKDAYS(K21,L21,$CB$3:$CB$19),NETWORKDAYS(K21,'2025整理'!$S$1,$CB$3:$CB$19)) -> 7 | R21: =IF(Q21="0",NETWORKDAYS(O21,P21,$EO$3:$EO$10),"") | V21: =IF(U21="0",NETWORKDAYS(S21,T21,$EO$3:$EO$11),"") | Z21: =IF(Y21="0",NETWORKDAYS(W21,X21,$EO$3:$EO$11),"") | AD21: =IF(AC21="0",NETWORKDAYS(AA21,AB21,$EO$3:$EO$11),"") | AE21: 方明 | AF21: 方明 | AG21: 王志会 | AH21: 2069.79 | AI21: 2072.09 | AJ21: 2050.17 | AK21: 2052.45 | AL21: =IF(AND(AK21<>"",AJ21<>""),IF(AK21>AJ21,"核增",IF(AK21<AJ21,"核减","不变")),"") -> 核增 | AM21: =IF(AND(AI21<>"",AH21<>""),MAX(ABS(AI21),ABS(AH21))-MIN(ABS(AI21),ABS(AH21)),"") -> 2.3 | AN21: =IF(AND(AK21<>"",AJ21<>""),MAX(ABS(AK21),ABS(AJ21))-MIN(ABS(AK21),ABS(AJ21)),"") -> 2.28 | AU21: 2064.33 | AV21: 2001.15 | AW21: 2044.82 | AX21: 1982.17 | AY21: =IF(AND(AX21<>"",AW21<>""),IF(AX21>AW21,"核增",IF(AX21<AW21,"核减","不变")),"") -> 核减 | AZ21: =IF(AND(AX21<>"",AW21<>""),MAX(ABS(AX21),ABS(AW21))-MIN(ABS(AX21),ABS(AW21)),"") -> 62.65 | BA21: =IF(AND(AV21<>"",AI21<>""),IF(AV21>AI21,"核增",IF(AV21<AI21,"核减","不变")),"")&TEXT(IF(AND(AV21<>"",AI21<>""),MAX(ABS(AV21),ABS(AI21))-MIN(ABS(AV21),ABS(AI21)),""),"0.00") -> 核减70.94 | BZ21: =IF(AND(BX21<>"",BW21<>""),MAX(ABS(BX21),ABS(BW21))-MIN(ABS(BX21),ABS(BW21)),"")
A22: 220kV教育城输变电工程（第二分册） | B22: 工程院 | F22: =IF(E22="0",NETWORKDAYS(C22,D22,$EO$3:$EO$11),"") | J22: =IF(I22="0",NETWORKDAYS(G22,H22,$EO$3:$EO$11),"") | K22: 45720 | L22: 45748 | M22: =IF(K22<>0,IF(L22<>0,"0","1"),"") -> 0 | N22: =IF(M22="0",NETWORKDAYS(K22,L22,$EO$3:$EO$11),"") -> 21 | R22: =IF(Q22="0",NETWORKDAYS(O22,P22,$EO$3:$EO$10),"") | S22: 45986 | T22: 45992 | U22: =IF(S22<>0,IF(T22<>0,"0","1"),"") -> 0 | V22: =IF(U22="0",NETWORKDAYS(S22,T22,$CB$3:$CB$19),NETWORKDAYS(S22,'2025整理'!$S$1,$CB$3:$CB$19)) -> 5 | Z22: =IF(Y22="0",NETWORKDAYS(W22,X22,$EO$3:$EO$11),"") | AD22: =IF(AC22="0",NETWORKDAYS(AA22,AB22,$EO$3:$EO$11),"") | AE22: 方明 | AF22: 方明 | AG22: 陈伟哲 | AI22: 18415.79 | AK22: 18100.64 | AU22: 17998.21 | AV22: 17514.06 | AW22: 17720.42 | AX22: 17243.52 | AY22: =IF(AND(AX22<>"",AW22<>""),IF(AX22>AW22,"核增",IF(AX22<AW22,"核减","不变")),"") -> 核减 | AZ22: =IF(AND(AX22<>"",AW22<>""),MAX(ABS(AX22),ABS(AW22))-MIN(ABS(AX22),ABS(AW22)),"") -> 476.9 | BA22: =IF(AND(AV22<>"",AI22<>""),IF(AV22>AI22,"核增",IF(AV22<AI22,"核减","不变")),"")&TEXT(IF(AND(AV22<>"",AI22<>""),MAX(ABS(AV22),ABS(AI22))-MIN(ABS(AV22),ABS(AI22)),""),"0.00") -> 核减901.73 | BH22: 16543.52 | BI22: 16488.34 | BJ22: 16288.21 | BK22: 16260.78 | BL22: =IF(AND(BK22<>"",BJ22<>""),IF(BK22>BJ22,"核增",IF(BK22<BJ22,"核减","不变")),"") -> 核减 | BM22: =IF(AND(BK22<>"",BJ22<>""),MAX(ABS(BK22),ABS(BJ22))-MIN(ABS(BK22),ABS(BJ22)),"") -> 27.43 | BN22: =IF(AND(BI22<>"",AV22<>""),IF(BI22>AV22,"核增",IF(BI22<AV22,"核减","不变")),"")&TEXT(IF(AND(BI22<>"",AV22<>""),MAX(ABS(BI22),ABS(AV22))-MIN(ABS(BI22),ABS(AV22)),""),"0.00") -> 核减1025.72
A23: 110kV黄阁站扩建第三台主变工程 | B23: 汇隽院 | F23: =IF(E23="0",NETWORKDAYS(C23,D23,$EO$3:$EO$11),"") | I23: =IF(G23<>0,IF(H23<>0,"0","1"),"") | K23: 45908 | L23: 45916 | M23: =IF(K23<>0,IF(L23<>0,"0","1"),"") -> 0 | N23: =IF(M23="0",NETWORKDAYS(K23,L23,$CB$3:$CB$19),NETWORKDAYS(K23,'2025整理'!$S$1,$CB$3:$CB$19)) -> 7 | R23: =IF(Q23="0",NETWORKDAYS(O23,P23,$EO$3:$EO$10),"") | V23: =IF(U23="0",NETWORKDAYS(S23,T23,$EO$3:$EO$11),"") | Z23: =IF(Y23="0",NETWORKDAYS(W23,X23,$EO$3:$EO$11),"") | AD23: =IF(AC23="0",NETWORKDAYS(AA23,AB23,$EO$3:$EO$11),"") | AE23: 樊心田 | AF23: 樊心田 | AG23: 黄小珈 | AI23: 2230.56 | AK23: 2203.7 | AU23: 2451.64 | AV23: 2335.41 | AW23: 2425.39 | AX23: 2310.62 | AY23: =IF(AND(AX23<>"",AW23<>""),IF(AX23>AW23,"核增",IF(AX23<AW23,"核减","不变")),"") -> 核减 | AZ23: =IF(AND(AX23<>"",AW23<>""),MAX(ABS(AX23),ABS(AW23))-MIN(ABS(AX23),ABS(AW23)),"") -> 114.77 | BA23: =IF(AND(AV23<>"",AI23<>""),IF(AV23>AI23,"核增",IF(AV23<AI23,"核减","不变")),"")&TEXT(IF(AND(AV23<>"",AI23<>""),MAX(ABS(AV23),ABS(AI23))-MIN(ABS(AV23),ABS(AI23)),""),"0.00") -> 核增104.85
A24: 220kV康祥输变电工程 | B24: 工程院 | F24: =IF(E24="0",NETWORKDAYS(C24,D24,$EO$3:$EO$11),"") | J24: =IF(I24="0",NETWORKDAYS(G24,H24,$EO$3:$EO$11),"") | K24: 46052 | M24: =IF(K24<>0,IF(L24<>0,"0","1"),"") -> 1 | N24: =IF(M24="0",NETWORKDAYS(K24,L24,$CB$3:$CB$19),NETWORKDAYS(K24,'2025整理'!$S$1,$CB$3:$CB$19)) -> -25 | R24: =IF(Q24="0",NETWORKDAYS(O24,P24,$EO$3:$EO$10),"") | V24: =IF(U24="0",NETWORKDAYS(S24,T24,$EO$3:$EO$11),"") | Z24: =IF(Y24="0",NETWORKDAYS(W24,X24,$EO$3:$EO$11),"") | AD24: =IF(AC24="0",NETWORKDAYS(AA24,AB24,$EO$3:$EO$11),"") | AE24: 方明 | AF24: 方明 | AG24: 陈伟哲 | AI24: 51020.04 | AK24: 50082.96 | AY24: =IF(AND(AX24<>"",AW24<>""),IF(AX24>AW24,"核增",IF(AX24<AW24,"核减","不变")),"") | BZ24: =IF(AND(BX24<>"",BW24<>""),MAX(ABS(BX24),ABS(BW24))-MIN(ABS(BX24),ABS(BW24)),"")
A25: 220kV界观（大沥）输变电工程（第二分册） | B25: 工程院 | J25: =IF(I25="0",NETWORKDAYS(G25,H25,$EO$3:$EO$11),"") | K25: 45642 | L25: 45683 | M25: =IF(K25<>0,IF(L25<>0,"0","1"),"") -> 0 | N25: =IF(M25="0",NETWORKDAYS(K25,L25,$EO$3:$EO$11),"") -> 30 | R25: =IF(Q25="0",NETWORKDAYS(O25,P25,$EO$3:$EO$10),"") | S25: 45818 | T25: 45877 | U25: =IF(S25<>0,IF(T25<>0,"0","1"),"") -> 0 | V25: =IF(U25="0",NETWORKDAYS(S25,T25,$CB$3:$CB$19),"") -> 44 | Z25: =IF(Y25="0",NETWORKDAYS(W25,X25,$EO$3:$EO$11),"") | AD25: =IF(AC25="0",NETWORKDAYS(AA25,AB25,$EO$3:$EO$11),"") | AE25: 谢瑞莲 | AF25: 谢瑞莲 | AG25: 陈伟哲 | AI25: 28224.01 | AK25: 27738.41 | AL25: =IF(AND(AK25<>"",AJ25<>""),IF(AK25>AJ25,"核增",IF(AK25<AJ25,"核减","不变")),"") | AM25: =IF(AND(AI25<>"",AH25<>""),MAX(ABS(AI25),ABS(AH25))-MIN(ABS(AI25),ABS(AH25)),"") | AN25: =IF(AND(AK25<>"",AJ25<>""),MAX(ABS(AK25),ABS(AJ25))-MIN(ABS(AK25),ABS(AJ25)),"") | AU25: 32110.29 | AV25: 28893.64 | AW25: 31612.22 | AX25: 28445.25 | AY25: =IF(AND(AX25<>"",AW25<>""),IF(AX25>AW25,"核增",IF(AX25<AW25,"核减","不变")),"") -> 核减 | AZ25: =IF(AND(AX25<>"",AW25<>""),MAX(ABS(AX25),ABS(AW25))-MIN(ABS(AX25),ABS(AW25)),"") -> 3166.97 | BA25: =IF(AND(AV25<>"",AI25<>""),IF(AV25>AI25,"核增",IF(AV25<AI25,"核减","不变")),"")&TEXT(IF(AND(AV25<>"",AI25<>""),MAX(ABS(AV25),ABS(AI25))-MIN(ABS(AV25),ABS(AI25)),""),"0.00") -> 核增669.63 | BH25: 27329.2 | BI25: 26725.07 | BJ25: 26905.22 | BK25: 26310.18 | BL25: =IF(AND(BK25<>"",BJ25<>""),IF(BK25>BJ25,"核增",IF(BK25<BJ25,"核减","不变")),"") -> 核减 | BM25: =IF(AND(BK25<>"",BJ25<>""),MAX(ABS(BK25),ABS(BJ25))-MIN(ABS(BK25),ABS(BJ25)),"") -> 595.04 | BN25: =IF(AND(BI25<>"",AV25<>""),IF(BI25>AV25,"核增",IF(BI25<AV25,"核减","不变")),"")&TEXT(IF(AND(BI25<>"",AV25<>""),MAX(ABS(BI25),ABS(AV25))-MIN(ABS(BI25),ABS(AV25)),""),"0.00") -> 核减2168.57 | BZ25: =IF(AND(BX25<>"",BW25<>""),MAX(ABS(BX25),ABS(BW25))-MIN(ABS(BX25),ABS(BW25)),"")
A26: 110kV湖石（源北）输变电工程（土建分册） | B26: 工程院 | J26: =IF(I26="0",NETWORKDAYS(G26,H26,$EO$3:$EO$11),"") | K26: 45650 | L26: 45667 | M26: =IF(K26<>0,IF(L26<>0,"0","1"),"") -> 0 | N26: =IF(M26="0",NETWORKDAYS(K26,L26,$CB$3:$CB$19),"") -> 13 | R26: =IF(Q26="0",NETWORKDAYS(O26,P26,$EO$3:$EO$10),"") | S26: 45806 | T26: 45825 | U26: =IF(S26<>0,IF(T26<>0,"0","1"),"") -> 0 | V26: =IF(U26="0",NETWORKDAYS(S26,T26,$CB$3:$CB$19),"") -> 14 | Z26: =IF(Y26="0",NETWORKDAYS(W26,X26,$EO$3:$EO$11),"") | AD26: =IF(AC26="0",NETWORKDAYS(AA26,AB26,$EO$3:$EO$11),"") | AE26: 樊心田 | AF26: 樊心田 | AG26: - | AI26: 4150.12 | AK26: 4078.88 | AL26: =IF(AND(AK26<>"",AJ26<>""),IF(AK26>AJ26,"核增",IF(AK26<AJ26,"核减","不变")),"") | AM26: =IF(AND(AI26<>"",AH26<>""),MAX(ABS(AI26),ABS(AH26))-MIN(ABS(AI26),ABS(AH26)),"") | AN26: =IF(AND(AK26<>"",AJ26<>""),MAX(ABS(AK26),ABS(AJ26))-MIN(ABS(AK26),ABS(AJ26)),"") | AU26: 4138.69 | AV26: 4123.48 | AW26: 4074.64 | AX26: 4059.67 | AY26: =IF(AND(AX26<>"",AW26<>""),IF(AX26>AW26,"核增",IF(AX26<AW26,"核减","不变")),"") -> 核减 | AZ26: =IF(AND(AX26<>"",AW26<>""),MAX(ABS(AX26),ABS(AW26))-MIN(ABS(AX26),ABS(AW26)),"") -> 14.97 | BA26: =IF(AND(AV26<>"",AI26<>""),IF(AV26>AI26,"核增",IF(AV26<AI26,"核减","不变")),"")&TEXT(IF(AND(AV26<>"",AI26<>""),MAX(ABS(AV26),ABS(AI26))-MIN(ABS(AV26),ABS(AI26)),""),"0.00") -> 核减26.64 | BH26: 3543.86 | BI26: 3748.44 | BJ26: 3483.03 | BK26: 3684.1 | BL26: =IF(AND(BK26<>"",BJ26<>""),IF(BK26>BJ26,"核增",IF(BK26<BJ26,"核减","不变")),"") -> 核增 | BM26: =IF(AND(BK26<>"",BJ26<>""),MAX(ABS(BK26),ABS(BJ26))-MIN(ABS(BK26),ABS(BJ26)),"") -> 201.07 | BN26: =IF(AND(BI26<>"",AV26<>""),IF(BI26>AV26,"核增",IF(BI26<AV26,"核减","不变")),"")&TEXT(IF(AND(BI26<>"",AV26<>""),MAX(ABS(BI26),ABS(AV26))-MIN(ABS(BI26),ABS(AV26)),""),"0.00") -> 核减375.04
A27: 110 kV中元输变电工程 | B27: 工程院 | F27: =IF(E27="0",NETWORKDAYS(C27,D27,$EO$3:$EO$11),"") | J27: =IF(I27="0",NETWORKDAYS(G27,H27,$EO$3:$EO$11),"") | K27: 45651 | L27: 45671 | M27: =IF(K27<>0,IF(L27<>0,"0","1"),"") -> 0 | N27: =IF(M27="0",NETWORKDAYS(K27,L27,$CB$3:$CB$19),"") -> 14 | S27: 45894 | T27: 45915 | U27: =IF(S27<>0,IF(T27<>0,"0","1"),"") -> 0 | V27: =IF(U27="0",NETWORKDAYS(S27,T27,$CB$3:$CB$19),"") -> 16 | AE27: 方明 | AF27: 方明 | AG27: 陈伟哲 | AI27: 11651.01 | AK27: 11451.05 | AU27: 10347.51 | AV27: 10503.94 | AW27: 10225.43 | AX27: 10362.78 | AY27: =IF(AND(AX27<>"",AW27<>""),IF(AX27>AW27,"核增",IF(AX27<AW27,"核减","不变")),"") -> 核增 | AZ27: =IF(AND(AX27<>"",AW27<>""),MAX(ABS(AX27),ABS(AW27))-MIN(ABS(AX27),ABS(AW27)),"") -> 137.35 | BA27: =IF(AND(AV27<>"",AI27<>""),IF(AV27>AI27,"核增",IF(AV27<AI27,"核减","不变")),"")&TEXT(IF(AND(AV27<>"",AI27<>""),MAX(ABS(AV27),ABS(AI27))-MIN(ABS(AV27),ABS(AI27)),""),"0.00") -> 核减1147.07 | BH27: 9277.03 | BI27: 9608.2 | BJ27: 9131.88 | BK27: 9459.51 | BL27: =IF(AND(BK27<>"",BJ27<>""),IF(BK27>BJ27,"核增",IF(BK27<BJ27,"核减","不变")),"") -> 核增 | BM27: =IF(AND(BK27<>"",BJ27<>""),MAX(ABS(BK27),ABS(BJ27))-MIN(ABS(BK27),ABS(BJ27)),"") -> 327.63 | BN27: =IF(AND(BI27<>"",AV27<>""),IF(BI27>AV27,"核增",IF(BI27<AV27,"核减","不变")),"")&TEXT(IF(AND(BI27<>"",AV27<>""),MAX(ABS(BI27),ABS(AV27))-MIN(ABS(BI27),ABS(AV27)),""),"0.00") -> 核减895.74
A28: 220kV蚌湖输变电工程（第二分册） | B28: 广州院 | I28: =IF(G28<>0,IF(H28<>0,"0","1"),"") | J28: =IF(I28="0",NETWORKDAYS(G28,H28,$EO$3:$EO$11),"") | K28: 45656 | L28: 45683 | M28: =IF(K28<>0,IF(L28<>0,"0","1"),"") -> 0 | N28: =IF(M28="0",NETWORKDAYS(K28,L28,$EO$3:$EO$11),"") -> 20 | Q28: =IF(O28<>0,IF(P28<>0,"0","1"),"") | R28: =IF(Q28="0",NETWORKDAYS(O28,P28,$EO$3:$EO$10),"") | S28: 45827 | T28: 45863 | U28: =IF(S28<>0,IF(T28<>0,"0","1"),"") -> 0 | V28: =IF(U28="0",NETWORKDAYS(S28,T28,$CB$3:$CB$19),"") -> 27 | Y28: =IF(W28<>0,IF(X28<>0,"0","1"),"") | Z28: =IF(Y28="0",NETWORKDAYS(W28,X28,$EO$3:$EO$11),"") | AC28: =IF(AA28<>0,IF(AB28<>0,"0","1"),"") | AD28: =IF(AC28="0",NETWORKDAYS(AA28,AB28,$EO$3:$EO$11),"") | AE28: 黄小珈 | AF28: - | AG28: 黄小珈 | AI28: 4700.57 | AK28: 4619.88 | AL28: =IF(AND(AK28<>"",AJ28<>""),IF(AK28>AJ28,"核增",IF(AK28<AJ28,"核减","不变")),"") | AM28: =IF(AND(AI28<>"",AH28<>""),MAX(ABS(AI28),ABS(AH28))-MIN(ABS(AI28),ABS(AH28)),"") | AN28: =IF(AND(AK28<>"",AJ28<>""),MAX(ABS(AK28),ABS(AJ28))-MIN(ABS(AK28),ABS(AJ28)),"") | AS28: =IF(AND(AR28<>"",AQ28<>""),IF(AR28>AQ28,"核增",IF(AR28<AQ28,"核减","不变")),"") | AT28: =IF(AND(AR28<>"",AQ28<>""),MAX(ABS(AR28),ABS(AQ28))-MIN(ABS(AR28),ABS(AQ28)),"") | AU28: 4462.28 | AV28: 4550.3 | AW28: 4393.23 | AX28: 4479.88 | AY28: =IF(AND(AX28<>"",AW28<>""),IF(AX28>AW28,"核增",IF(AX28<AW28,"核减","不变")),"") -> 核增 | AZ28: =IF(AND(AX28<>"",AW28<>""),MAX(ABS(AX28),ABS(AW28))-MIN(ABS(AX28),ABS(AW28)),"") -> 86.65 | BA28: =IF(AND(AV28<>"",AI28<>""),IF(AV28>AI28,"核增",IF(AV28<AI28,"核减","不变")),"")&TEXT(IF(AND(AV28<>"",AI28<>""),MAX(ABS(AV28),ABS(AI28))-MIN(ABS(AV28),ABS(AI28)),""),"0.00") -> 核减150.27 | BF28: =IF(AND(BE28<>"",BD28<>""),IF(BE28>BD28,"核增",IF(BE28<BD28,"核减","不变")),"") | BH28: 4109.42 | BI28: 4291.37 | BJ28: 4045.76 | BK28: 4224.96 | BL28: =IF(AND(BK28<>"",BJ28<>""),IF(BK28>BJ28,"核增",IF(BK28<BJ28,"核减","不变")),"") -> 核增 | BM28: =IF(AND(BK28<>"",BJ28<>""),MAX(ABS(BK28),ABS(BJ28))-MIN(ABS(BK28),ABS(BJ28)),"") -> 179.2 | BN28: =IF(AND(BI28<>"",AV28<>""),IF(BI28>AV28,"核增",IF(BI28<AV28,"核减","不变")),"")&TEXT(IF(AND(BI28<>"",AV28<>""),MAX(ABS(BI28),ABS(AV28))-MIN(ABS(BI28),ABS(AV28)),""),"0.00") -> 核减258.93 | BS28: =IF(AND(BR28<>"",BQ28<>""),IF(BR28>BQ28,"核增",IF(BR28<BQ28,"核减","不变")),"") | BT28: =IF(AND(BR28<>"",BQ28<>""),MAX(ABS(BR28),ABS(BQ28))-MIN(ABS(BR28),ABS(BQ28)),"") | BY28: =IF(AND(BX28<>"",BW28<>""),IF(BX28>BW28,"核增",IF(BX28<BW28,"核减","不变")),"") | BZ28: =IF(AND(BX28<>"",BW28<>""),MAX(ABS(BX28),ABS(BW28))-MIN(ABS(BX28),ABS(BW28)),"")
A29: 110kV广场输变电工程（电气分册） | B29: 汇隽院 | F29: =IF(E29="0",NETWORKDAYS(C29,D29,$EO$3:$EO$11),"") | J29: =IF(I29="0",NETWORKDAYS(G29,H29,$EO$3:$EO$11),"") | K29: 45712 | L29: 45720 | M29: =IF(K29<>0,IF(L29<>0,"0","1"),"") -> 0 | N29: =IF(M29="0",NETWORKDAYS(K29,L29,$EO$3:$EO$11),"") -> 7 | R29: =IF(Q29="0",NETWORKDAYS(O29,P29,$EO$3:$EO$10),"") | S29: 45877 | T29: 45888 | U29: =IF(S29<>0,IF(T29<>0,"0","1"),"") -> 0 | V29: =IF(U29="0",NETWORKDAYS(S29,T29,$CB$3:$CB$19),NETWORKDAYS(S29,'2025整理'!$S$1,$CB$3:$CB$19)) -> 8 | Z29: =IF(Y29="0",NETWORKDAYS(W29,X29,$EO$3:$EO$11),"") | AD29: =IF(AC29="0",NETWORKDAYS(AA29,AB29,$EO$3:$EO$11),"") | AE29: 樊心田 | AF29: 樊心田 | AG29: 陈伟哲 | AI29: 9318.27 | AK29: 9159.17 | AU29: 8789.4 | AV29: 9068.62 | AW29: 8654.04 | AX29: 8928.98 | AY29: =IF(AND(AX29<>"",AW29<>""),IF(AX29>AW29,"核增",IF(AX29<AW29,"核减","不变")),"") -> 核增 | AZ29: =IF(AND(AX29<>"",AW29<>""),MAX(ABS(AX29),ABS(AW29))-MIN(ABS(AX29),ABS(AW29)),"") -> 274.94 | BA29: =IF(AND(AV29<>"",AI29<>""),IF(AV29>AI29,"核增",IF(AV29<AI29,"核减","不变")),"")&TEXT(IF(AND(AV29<>"",AI29<>""),MAX(ABS(AV29),ABS(AI29))-MIN(ABS(AV29),ABS(AI29)),""),"0.00") -> 核减249.65 | BH29: 9060.94 | BI29: 9051.49 | BJ29: 8921.61 | BK29: 8912.25 | BL29: =IF(AND(BK29<>"",BJ29<>""),IF(BK29>BJ29,"核增",IF(BK29<BJ29,"核减","不变")),"") -> 核减 | BM29: =IF(AND(BK29<>"",BJ29<>""),MAX(ABS(BK29),ABS(BJ29))-MIN(ABS(BK29),ABS(BJ29)),"") -> 9.36 | BN29: =IF(AND(BI29<>"",AV29<>""),IF(BI29>AV29,"核增",IF(BI29<AV29,"核减","不变")),"")&TEXT(IF(AND(BI29<>"",AV29<>""),MAX(ABS(BI29),ABS(AV29))-MIN(ABS(BI29),ABS(AV29)),""),"0.00") -> 核减17.13 | BZ29: =IF(AND(BX29<>"",BW29<>""),MAX(ABS(BX29),ABS(BW29))-MIN(ABS(BX29),ABS(BW29)),"")
A30: 医药港110kV出线至冲口线路工程 | B30: 广州院 | J30: =IF(I30="0",NETWORKDAYS(G30,H30,$EO$3:$EO$11),"") | K30: 45776 | L30: 45777 | M30: =IF(K30<>0,IF(L30<>0,"0","1"),"") -> 0 | N30: =IF(M30="0",NETWORKDAYS(K30,L30,$EO$3:$EO$11),"") -> 2 | R30: =IF(Q30="0",NETWORKDAYS(O30,P30,$EO$3:$EO$10),"") | S30: 46017 | U30: =IF(S30<>0,IF(T30<>0,"0","1"),"") -> 1 | V30: =IF(U30="0",NETWORKDAYS(S30,T30,$CB$3:$CB$19),NETWORKDAYS(S30,'2025整理'!$S$1,$CB$3:$CB$19)) -> 2 | Z30: =IF(Y30="0",NETWORKDAYS(W30,X30,$EO$3:$EO$11),"") | AD30: =IF(AC30="0",NETWORKDAYS(AA30,AB30,$EO$3:$EO$11),"") | AE30: 黄小珈 | AF30: 方明 | AG30: 黄小珈 | AI30: 11930.84 | AK30: 11727.53 | AL30: =IF(AND(AK30<>"",AJ30<>""),IF(AK30>AJ30,"核增",IF(AK30<AJ30,"核减","不变")),"") | AM30: =IF(AND(AI30<>"",AH30<>""),MAX(ABS(AI30),ABS(AH30))-MIN(ABS(AI30),ABS(AH30)),"") | AN30: =IF(AND(AK30<>"",AJ30<>""),MAX(ABS(AK30),ABS(AJ30))-MIN(ABS(AK30),ABS(AJ30)),"") | AS30: =IF(AND(AR30<>"",AQ30<>""),IF(AR30>AQ30,"核增",IF(AR30<AQ30,"核减","不变")),"") | AT30: =IF(AND(AR30<>"",AQ30<>""),MAX(ABS(AR30),ABS(AQ30))-MIN(ABS(AR30),ABS(AQ30)),"") | AU30: 12199.39 | AV30: 12454.12 | AW30: 12012.58 | AX30: 12262.73 | AY30: =IF(AND(AX30<>"",AW30<>""),IF(AX30>AW30,"核增",IF(AX30<AW30,"核减","不变")),"") -> 核增 | AZ30: =IF(AND(AX30<>"",AW30<>""),MAX(ABS(AX30),ABS(AW30))-MIN(ABS(AX30),ABS(AW30)),"") -> 250.15 | BA30: =IF(AND(AV30<>"",AI30<>""),IF(AV30>AI30,"核增",IF(AV30<AI30,"核减","不变")),"")&TEXT(IF(AND(AV30<>"",AI30<>""),MAX(ABS(AV30),ABS(AI30))-MIN(ABS(AV30),ABS(AI30)),""),"0.00") -> 核增523.28 | BF30: =IF(AND(BE30<>"",BD30<>""),IF(BE30>BD30,"核增",IF(BE30<BD30,"核减","不变")),"") | BL30: =IF(AND(BK30<>"",BJ30<>""),IF(BK30>BJ30,"核增",IF(BK30<BJ30,"核减","不变")),"") | BM30: =IF(AND(BK30<>"",BJ30<>""),MAX(ABS(BK30),ABS(BJ30))-MIN(ABS(BK30),ABS(BJ30)),"") | BN30: =IF(AND(BI30<>"",AV30<>""),IF(BI30>AV30,"核增",IF(BI30<AV30,"核减","不变")),"")&TEXT(IF(AND(BI30<>"",AV30<>""),MAX(ABS(BI30),ABS(AV30))-MIN(ABS(BI30),ABS(AV30)),""),"0.00") | BS30: =IF(AND(BR30<>"",BQ30<>""),IF(BR30>BQ30,"核增",IF(BR30<BQ30,"核减","不变")),"") | BT30: =IF(AND(BR30<>"",BQ30<>""),MAX(ABS(BR30),ABS(BQ30))-MIN(ABS(BR30),ABS(BQ30)),"") | BY30: =IF(AND(BX30<>"",BW30<>""),IF(BX30>BW30,"核增",IF(BX30<BW30,"核减","不变")),"")
A31: 110kV南景园输变电工程（电气分册） | B31: 工程院 | C31: 45877 | D31: 45916 | E31: =IF(C31<>0,IF(D31<>0,"0","1"),"") -> 0 | F31: =IF(E31="0",NETWORKDAYS(C31,D31,$CB$3:$CB$19),NETWORKDAYS(C31,'2025整理'!$S$1,$CB$3:$CB$19)) -> 28 | I31: =IF(G31<>0,IF(H31<>0,"0","1"),"") | K31: 46009 | M31: =IF(K31<>0,IF(L31<>0,"0","1"),"") -> 1 | N31: =IF(M31="0",NETWORKDAYS(K31,L31,$CB$3:$CB$19),NETWORKDAYS(K31,'2025整理'!$S$1,$CB$3:$CB$19)) -> 8 | R31: =IF(Q31="0",NETWORKDAYS(O31,P31,$EO$3:$EO$10),"") | V31: =IF(U31="0",NETWORKDAYS(S31,T31,$EO$3:$EO$11),"") | Z31: =IF(Y31="0",NETWORKDAYS(W31,X31,$EO$3:$EO$11),"") | AD31: =IF(AC31="0",NETWORKDAYS(AA31,AB31,$EO$3:$EO$11),"") | AE31: 方明 | AF31: 方明 | AG31: 黄小珈 | AH31: 10614.23 | AI31: 10744.17 | AJ31: 10432.73 | AK31: 10561.23 | AL31: =IF(AND(AK31<>"",AJ31<>""),IF(AK31>AJ31,"核增",IF(AK31<AJ31,"核减","不变")),"") -> 核增 | AM31: =IF(AND(AI31<>"",AH31<>""),MAX(ABS(AI31),ABS(AH31))-MIN(ABS(AI31),ABS(AH31)),"") -> 129.94 | AN31: =IF(AND(AK31<>"",AJ31<>""),MAX(ABS(AK31),ABS(AJ31))-MIN(ABS(AK31),ABS(AJ31)),"") -> 128.5 | AY31: =IF(AND(AX31<>"",AW31<>""),IF(AX31>AW31,"核增",IF(AX31<AW31,"核减","不变")),"")
A32: 110kV智信输变电工程 | B32: 工程院 | F32: =IF(E32="0",NETWORKDAYS(C32,D32,$EO$3:$EO$11),"") | J32: =IF(I32="0",NETWORKDAYS(G32,H32,$EO$3:$EO$11),"") | S32: 46052 | U32: =IF(S32<>0,IF(T32<>0,"0","1"),"") -> 1 | V32: =IF(U32="0",NETWORKDAYS(S32,T32,$CB$3:$CB$19),NETWORKDAYS(S32,'2025整理'!$S$1,$CB$3:$CB$19)) -> -25 | AE32: 方明 | AF32: 方明 | AG32: 陈伟哲 | AY32: =IF(AND(AX32<>"",AW32<>""),IF(AX32>AW32,"核增",IF(AX32<AW32,"核减","不变")),"")
A33: 梨园变电站对侧及线路第二分册（嘉禾侧） | B33: 广州院 | F33: =IF(E33="0",NETWORKDAYS(C33,D33,$EO$3:$EO$11),"") | J33: =IF(I33="0",NETWORKDAYS(G33,H33,$EO$3:$EO$11),"") | S33: 45818 | T33: 45826 | U33: =IF(S33<>0,IF(T33<>0,"0","1"),"") -> 0 | V33: =IF(U33="0",NETWORKDAYS(S33,T33,$CB$3:$CB$19),"") -> 7 | AE33: 方明 | AF33: 方明 | AG33: 陈伟哲 | AV33: 21296.6 | AX33: 20970.45 | AY33: =IF(AND(AX33<>"",AW33<>""),IF(AX33>AW33,"核增",IF(AX33<AW33,"核减","不变")),"") | BH33: 19215.53 | BI33: 15906.16 | BJ33: 18905.26 | BK33: 15651.02 | BL33: =IF(AND(BK33<>"",BJ33<>""),IF(BK33>BJ33,"核增",IF(BK33<BJ33,"核减","不变")),"") -> 核减 | BM33: =IF(AND(BK33<>"",BJ33<>""),MAX(ABS(BK33),ABS(BJ33))-MIN(ABS(BK33),ABS(BJ33)),"") -> 3254.24 | BN33: =IF(AND(BI33<>"",AV33<>""),IF(BI33>AV33,"核增",IF(BI33<AV33,"核减","不变")),"")&TEXT(IF(AND(BI33<>"",AV33<>""),MAX(ABS(BI33),ABS(AV33))-MIN(ABS(BI33),ABS(AV33)),""),"0.00") -> 核减5390.44
A34: 110kV板头输变电工程(变电站部分) | B34: 汇隽院 | F34: =IF(E34="0",NETWORKDAYS(C34,D34,$EO$3:$EO$11),"") | I34: =IF(G34<>0,IF(H34<>0,"0","1"),"") | J34: =IF(I34="0",NETWORKDAYS(G34,H34,$EO$3:$EO$11),"") | R34: =IF(Q34="0",NETWORKDAYS(O34,P34,$EO$3:$EO$10),"") | S34: 45648 | T34: 45667 | U34: =IF(S34<>0,IF(T34<>0,"0","1"),"") -> 0 | V34: =IF(U34="0",NETWORKDAYS(S34,T34,$CB$3:$CB$19),"") -> 14 | Z34: =IF(Y34="0",NETWORKDAYS(S34,T34,$EO$3:$EO$11),"") | AD34: =IF(AC34="0",NETWORKDAYS(AA34,AB34,$EO$3:$EO$11),"") | AE34: 方明 | AF34: 方明 | AG34: 陈伟哲 | AI34: 12366 | AK34: 12146 | AS34: =IF(AND(AR34<>"",AQ34<>""),IF(AR34>AQ34,"核增",IF(AR34<AQ34,"核减","不变")),"") | AT34: =IF(AND(AR34<>"",AQ34<>""),MAX(ABS(AR34),ABS(AQ34))-MIN(ABS(AR34),ABS(AQ34)),"") | AV34: 14607.59 | AX34: 14381.67 | AY34: =IF(AND(AX34<>"",AW34<>""),IF(AX34>AW34,"核增",IF(AX34<AW34,"核减","不变")),"") | AZ34: =IF(AND(AX34<>"",AW34<>""),MAX(ABS(AX34),ABS(AW34))-MIN(ABS(AX34),ABS(AW34)),"") | BH34: 14843.17 | BI34: 14194.54 | BJ34: 14613.59 | BK34: 13975.01 | BL34: =IF(AND(BK34<>"",BJ34<>""),IF(BK34>BJ34,"核增",IF(BK34<BJ34,"核减","不变")),"") -> 核减 | BM34: =IF(AND(BK34<>"",BJ34<>""),MAX(ABS(BK34),ABS(BJ34))-MIN(ABS(BK34),ABS(BJ34)),"") -> 638.58 | BN34: =IF(AND(BI34<>"",AV34<>""),IF(BI34>AV34,"核增",IF(BI34<AV34,"核减","不变")),"")&TEXT(IF(AND(BI34<>"",AV34<>""),MAX(ABS(BI34),ABS(AV34))-MIN(ABS(BI34),ABS(AV34)),""),"0.00") -> 核减413.05
A35: 110kV白沙（良沙）输变电工程 | B35: 广州院 | I35: =IF(G35<>0,IF(H35<>0,"0","1"),"") | J35: =IF(I35="0",NETWORKDAYS(G35,H35,$EO$3:$EO$11),"") | Q35: =IF(O35<>0,IF(P35<>0,"0","1"),"") | R35: =IF(Q35="0",NETWORKDAYS(O35,P35,$EO$3:$EO$10),"") | S35: 45716 | T35: 45719 | U35: =IF(S35<>0,IF(T35<>0,"0","1"),"") -> 0 | V35: =IF(U35="0",NETWORKDAYS(S35,T35,$CB$3:$CB$19),"") -> 2 | AC35: =IF(AA35<>0,IF(AB35<>0,"0","1"),"") | AD35: =IF(AC35="0",NETWORKDAYS(AA35,AB35,$EO$3:$EO$11),"") | AE35: 方明 | AF35: 方明 | AG35: 陈伟哲 | AI35: 18165.74 | AK35: 17854.02 | AL35: =IF(AND(AK35<>"",AJ35<>""),IF(AK35>AJ35,"核增",IF(AK35<AJ35,"核减","不变")),"") | AM35: =IF(AND(AI35<>"",AH35<>""),MAX(ABS(AI35),ABS(AH35))-MIN(ABS(AI35),ABS(AH35)),"") | AN35: =IF(AND(AK35<>"",AJ35<>""),MAX(ABS(AK35),ABS(AJ35))-MIN(ABS(AK35),ABS(AJ35)),"") | AS35: =IF(AND(AR35<>"",AQ35<>""),IF(AR35>AQ35,"核增",IF(AR35<AQ35,"核减","不变")),"") | AT35: =IF(AND(AR35<>"",AQ35<>""),MAX(ABS(AR35),ABS(AQ35))-MIN(ABS(AR35),ABS(AQ35)),"") | AV35: 17618.6 | AX35: 17331.58 | AY35: =IF(AND(AX35<>"",AW35<>""),IF(AX35>AW35,"核增",IF(AX35<AW35,"核减","不变")),"") | AZ35: =IF(AND(AX35<>"",AW35<>""),MAX(ABS(AX35),ABS(AW35))-MIN(ABS(AX35),ABS(AW35)),"") | BF35: =IF(AND(BE35<>"",BD35<>""),IF(BE35>BD35,"核增",IF(BE35<BD35,"核减","不变")),"") | BH35: 17618.6 | BI35: 16407.33 | BJ35: 16036.19 | BK35: 16153.49 | BL35: =IF(AND(BK35<>"",BJ35<>""),IF(BK35>BJ35,"核增",IF(BK35<BJ35,"核减","不变")),"") -> 核增 | BM35: =IF(AND(BK35<>"",BJ35<>""),MAX(ABS(BK35),ABS(BJ35))-MIN(ABS(BK35),ABS(BJ35)),"") -> 117.3 | BN35: =IF(AND(BI35<>"",AV35<>""),IF(BI35>AV35,"核增",IF(BI35<AV35,"核减","不变")),"")&TEXT(IF(AND(BI35<>"",AV35<>""),MAX(ABS(BI35),ABS(AV35))-MIN(ABS(BI35),ABS(AV35)),""),"0.00") -> 核减1211.27 | BS35: =IF(AND(BR35<>"",BQ35<>""),IF(BR35>BQ35,"核增",IF(BR35<BQ35,"核减","不变")),"") | BT35: =IF(AND(BR35<>"",BQ35<>""),MAX(ABS(BR35),ABS(BQ35))-MIN(ABS(BR35),ABS(BQ35)),"") | BY35: =IF(AND(BX35<>"",BW35<>""),IF(BX35>BW35,"核增",IF(BX35<BW35,"核减","不变")),"")
A36: 110千伏中市输变电工程（土建分册） | B36: 工程院 | F36: =IF(E36="0",NETWORKDAYS(C36,D36,$EO$3:$EO$11),"") | J36: =IF(I36="0",NETWORKDAYS(G36,H36,$EO$3:$EO$11),"") | R36: =IF(Q36="0",NETWORKDAYS(O36,P36,$EO$3:$EO$10),"") | S36: 45666 | T36: 45679 | U36: =IF(S36<>0,IF(T36<>0,"0","1"),"") -> 0 | V36: =IF(U36="0",NETWORKDAYS(S36,T36,$CB$3:$CB$19),"") -> 10 | Z36: =IF(Y36="0",NETWORKDAYS(S36,T36,$EO$3:$EO$11),"") | AD36: =IF(AC36="0",NETWORKDAYS(AA36,AB36,$EO$3:$EO$11),"") | AE36: 樊心田 | AF36: 樊心田 | AG36: - | AI36: 3822.38 | AK36: 3756.77 | AV36: 3727.74 | AX36: 3670.55 | AY36: =IF(AND(AX36<>"",AW36<>""),IF(AX36>AW36,"核增",IF(AX36<AW36,"核减","不变")),"") | AZ36: =IF(AND(AX36<>"",AW36<>""),MAX(ABS(AX36),ABS(AW36))-MIN(ABS(AX36),ABS(AW36)),"") | BH36: 3579.83 | BI36: 3544.96 | BJ36: 3524.93 | BK36: 3490.6 | BL36: =IF(AND(BK36<>"",BJ36<>""),IF(BK36>BJ36,"核增",IF(BK36<BJ36,"核减","不变")),"") -> 核减 | BM36: =IF(AND(BK36<>"",BJ36<>""),MAX(ABS(BK36),ABS(BJ36))-MIN(ABS(BK36),ABS(BJ36)),"") -> 34.33 | BN36: =IF(AND(BI36<>"",AV36<>""),IF(BI36>AV36,"核增",IF(BI36<AV36,"核减","不变")),"")&TEXT(IF(AND(BI36<>"",AV36<>""),MAX(ABS(BI36),ABS(AV36))-MIN(ABS(BI36),ABS(AV36)),""),"0.00") -> 核减182.78
A37: 110kV群结输变电工程（土建分册） | B37: 汇隽院 | J37: =IF(I37="0",NETWORKDAYS(G37,H37,$EO$3:$EO$42),"") | N37: =IF(M37="0",NETWORKDAYS(K37,L37,$EO$3:$EO$42),"") | S37: 45671 | T37: 45684 | U37: =IF(S37<>0,IF(T37<>0,"0","1"),"") -> 0 | V37: =IF(U37="0",NETWORKDAYS(S37,T37,$CB$3:$CB$19),"") -> 10 | Z37: =IF(Y37="0",NETWORKDAYS(S37,T37,$EO$3:$EO$42),"") | AD37: =IF(AC37="0",NETWORKDAYS(AA37,AB37,$EO$3:$EO$42),"") | AE37: 樊心田 | AF37: 樊心田 | AG37: - | AS37: =IF(AND(AR37<>"",AQ37<>""),IF(AR37>AQ37,"核增",IF(AR37<AQ37,"核减","不变")),"") | AT37: =IF(AND(AR37<>"",AQ37<>""),MAX(ABS(AR37),ABS(AQ37))-MIN(ABS(AR37),ABS(AQ37)),"") | AV37: 4716.95 | AX37: 4643.95 | AY37: =IF(AND(AX37<>"",AW37<>""),IF(AX37>AW37,"核增",IF(AX37<AW37,"核减","不变")),"") | AZ37: =IF(AND(AX37<>"",AW37<>""),MAX(ABS(AX37),ABS(AW37))-MIN(ABS(AX37),ABS(AW37)),"") | BF37: =IF(AND(BE37<>"",BD37<>""),IF(BE37>BD37,"核增",IF(BE37<BD37,"核减","不变")),"") | BG37: =IF(AND(BE37<>"",BD37<>""),MAX(ABS(BE37),ABS(BD37))-MIN(ABS(BE37),ABS(BD37)),"") | BH37: 4654.21 | BI37: 4490.48 | BJ37: 4582.19 | BK37: 4420.99 | BL37: =IF(AND(BK37<>"",BJ37<>""),IF(BK37>BJ37,"核增",IF(BK37<BJ37,"核减","不变")),"") -> 核减 | BM37: =IF(AND(BK37<>"",BJ37<>""),MAX(ABS(BK37),ABS(BJ37))-MIN(ABS(BK37),ABS(BJ37)),"") -> 161.2 | BN37: =IF(AND(BI37<>"",AV37<>""),IF(BI37>AV37,"核增",IF(BI37<AV37,"核减","不变")),"")&TEXT(IF(AND(BI37<>"",AV37<>""),MAX(ABS(BI37),ABS(AV37))-MIN(ABS(BI37),ABS(AV37)),""),"0.00") -> 核减226.47
A38: 110kV较场站第三台主变扩建工程 | B38: 广州院 | J38: =IF(I38="0",NETWORKDAYS(G38,H38,$EO$3:$EO$11),"") | R38: =IF(Q38="0",NETWORKDAYS(O38,P38,$EO$3:$EO$10),"") | S38: 45705 | T38: 45713 | U38: =IF(S38<>0,IF(T38<>0,"0","1"),"") -> 0 | V38: =IF(U38="0",NETWORKDAYS(S38,T38,$CB$3:$CB$19),"") -> 7 | Z38: =IF(Y38="0",NETWORKDAYS(S38,T38,$EO$3:$EO$11),"") | AD38: =IF(AC38="0",NETWORKDAYS(AA38,AB38,$EO$3:$EO$11),"") | AE38: 樊心田 | AF38: 樊心田 | AG38: 陈伟哲 | AI38: 4559.13 | AK38: 4492.22 | AL38: =IF(AND(AK38<>"",AJ38<>""),IF(AK38>AJ38,"核增",IF(AK38<AJ38,"核减","不变")),"") | AM38: =IF(AND(AI38<>"",AH38<>""),MAX(ABS(AI38),ABS(AH38))-MIN(ABS(AI38),ABS(AH38)),"") | AN38: =IF(AND(AK38<>"",AJ38<>""),MAX(ABS(AK38),ABS(AJ38))-MIN(ABS(AK38),ABS(AJ38)),"") | AS38: =IF(AND(AR38<>"",AQ38<>""),IF(AR38>AQ38,"核增",IF(AR38<AQ38,"核减","不变")),"") | AT38: =IF(AND(AR38<>"",AQ38<>""),MAX(ABS(AR38),ABS(AQ38))-MIN(ABS(AR38),ABS(AQ38)),"") | AV38: 4516.9 | AX38: 4457.14 | AY38: =IF(AND(AX38<>"",AW38<>""),IF(AX38>AW38,"核增",IF(AX38<AW38,"核减","不变")),"") | AZ38: =IF(AND(AX38<>"",AW38<>""),MAX(ABS(AX38),ABS(AW38))-MIN(ABS(AX38),ABS(AW38)),"") | BF38: =IF(AND(BE38<>"",BD38<>""),IF(BE38>BD38,"核增",IF(BE38<BD38,"核减","不变")),"") | BH38: 3758.78 | BI38: 4101.32 | BJ38: 3710.08 | BK38: 4047.45 | BL38: =IF(AND(BK38<>"",BJ38<>""),IF(BK38>BJ38,"核增",IF(BK38<BJ38,"核减","不变")),"") -> 核增 | BM38: =IF(AND(BK38<>"",BJ38<>""),MAX(ABS(BK38),ABS(BJ38))-MIN(ABS(BK38),ABS(BJ38)),"") -> 337.37 | BN38: =IF(AND(BI38<>"",AV38<>""),IF(BI38>AV38,"核增",IF(BI38<AV38,"核减","不变")),"")&TEXT(IF(AND(BI38<>"",AV38<>""),MAX(ABS(BI38),ABS(AV38))-MIN(ABS(BI38),ABS(AV38)),""),"0.00") -> 核减415.58 | BS38: =IF(AND(BR38<>"",BQ38<>""),IF(BR38>BQ38,"核增",IF(BR38<BQ38,"核减","不变")),"") | BT38: =IF(AND(BR38<>"",BQ38<>""),MAX(ABS(BR38),ABS(BQ38))-MIN(ABS(BR38),ABS(BQ38)),"") | BY38: =IF(AND(BX38<>"",BW38<>""),IF(BX38>BW38,"核增",IF(BX38<BW38,"核减","不变")),"")
A39: 220kV伟业输变电工程（土建分册） | B39: 工程院 | F39: =IF(E39="0",NETWORKDAYS(C39,D39,$EO$3:$EO$11),"") | J39: =IF(I39="0",NETWORKDAYS(G39,H39,$EO$3:$EO$11),"") | R39: =IF(Q39="0",NETWORKDAYS(O39,P39,$EO$3:$EO$10),"") | S39: 45678 | T39: 45683 | U39: =IF(S39<>0,IF(T39<>0,"0","1"),"") -> 0 | V39: =IF(U39="0",NETWORKDAYS(S39,T39,$CB$3:$CB$19),"") -> 4 | Z39: =IF(Y39="0",NETWORKDAYS(S39,T39,$EO$3:$EO$11),"") | AD39: =IF(AC39="0",NETWORKDAYS(AA39,AB39,$EO$3:$EO$11),"") | AE39: 樊心田 | AF39: 樊心田 | AG39: - | AI39: 8250.75 | AK39: 8099.19 | AV39: 7652.97 | AX39: 7526.22 | AY39: =IF(AND(AX39<>"",AW39<>""),IF(AX39>AW39,"核增",IF(AX39<AW39,"核减","不变")),"") | AZ39: =IF(AND(AX39<>"",AW39<>""),MAX(ABS(AX39),ABS(AW39))-MIN(ABS(AX39),ABS(AW39)),"") | BH39: 7810.61 | BI39: 7617.84 | BJ39: 7681.25 | BK39: 7491.67 | BL39: =IF(AND(BK39<>"",BJ39<>""),IF(BK39>BJ39,"核增",IF(BK39<BJ39,"核减","不变")),"") -> 核减 | BM39: =IF(AND(BK39<>"",BJ39<>""),MAX(ABS(BK39),ABS(BJ39))-MIN(ABS(BK39),ABS(BJ39)),"") -> 189.58 | BN39: =IF(AND(BI39<>"",AV39<>""),IF(BI39>AV39,"核增",IF(BI39<AV39,"核减","不变")),"")&TEXT(IF(AND(BI39<>"",AV39<>""),MAX(ABS(BI39),ABS(AV39))-MIN(ABS(BI39),ABS(AV39)),""),"0.00") -> 核减35.13 | BZ39: =IF(AND(BX39<>"",BW39<>""),MAX(ABS(BX39),ABS(BW39))-MIN(ABS(BX39),ABS(BW39)),"")
A40: 面向特大城市电网能源互联网示范项目（110kV尖峰变电站二期配套工程） | B40: 省院 | E40: =IF(C40<>0,IF(D40<>0,"0","1"),"") | F40: =IF(E40="0",NETWORKDAYS(C40,D40,$EO$3:$EO$11),"") | I40: =IF(G40<>0,IF(H40<>0,"0","1"),"") | J40: =IF(I40="0",NETWORKDAYS(G40,H40,$EO$3:$EO$11),"") | N40: =IF(M40="0",NETWORKDAYS(K40,L40,$EO$3:$EO$11),"") | Q40: =IF(O40<>0,IF(P40<>0,"0","1"),"") | R40: =IF(Q40="0",NETWORKDAYS(O40,P40,$EO$3:$EO$10),"") | S40: 45839 | T40: 45856 | U40: =IF(S40<>0,IF(T40<>0,"0","1"),"") -> 0 | V40: =IF(U40="0",NETWORKDAYS(S40,T40,$CB$3:$CB$19),"") -> 14 | AC40: =IF(AA40<>0,IF(AB40<>0,"0","1"),"") | AD40: =IF(AC40="0",NETWORKDAYS(AA40,AB40,$EO$3:$EO$11),"") | AE40: 方明 | AF40: 方明 | AG40: - | AI40: 14502 | AK40: 14253 | AP40: 19059.14 | AR40: 18922.56 | AS40: =IF(AND(AR40<>"",AQ40<>""),IF(AR40>AQ40,"核增",IF(AR40<AQ40,"核减","不变")),"") | AT40: =IF(AND(AR40<>"",AQ40<>""),MAX(ABS(AR40),ABS(AQ40))-MIN(ABS(AR40),ABS(AQ40)),"") | AV40: 8466.43 | AX40: 8466.43 | AY40: =IF(AND(AX40<>"",AW40<>""),IF(AX40>AW40,"核增",IF(AX40<AW40,"核减","不变")),"") | BC40: 18632.46 | BE40: 18586.77 | BF40: =IF(AND(BE40<>"",BD40<>""),IF(BE40>BD40,"核增",IF(BE40<BD40,"核减","不变")),"") | BG40: =IF(AND(BE40<>"",BD40<>""),MAX(ABS(BE40),ABS(BD40))-MIN(ABS(BE40),ABS(BD40)),"") | BH40: 8456.78 | BI40: 8456.78 | BJ40: 8456.78 | BK40: 8456.78 | BL40: =IF(AND(BK40<>"",BJ40<>""),IF(BK40>BJ40,"核增",IF(BK40<BJ40,"核减","不变")),"") -> 不变 | BM40: =IF(AND(BK40<>"",BJ40<>""),MAX(ABS(BK40),ABS(BJ40))-MIN(ABS(BK40),ABS(BJ40)),"") -> 0 | BN40: =IF(AND(BI40<>"",AV40<>""),IF(BI40>AV40,"核增",IF(BI40<AV40,"核减","不变")),"")&TEXT(IF(AND(BI40<>"",AV40<>""),MAX(ABS(BI40),ABS(AV40))-MIN(ABS(BI40),ABS(AV40)),""),"0.00") -> 核减9.65
...

Sheet 2025整理
A1: 设计阶段 | B1: 评审阶段 | C1: 统计维度 | D1: 单位 | E1: 统计项目 | F1: 1月 | G1: 2月 | H1: 3月 | I1: 4月 | J1: 5月 | K1: 6月 | L1: 7月 | M1: 8月 | N1: 9月 | O1: 10月 | P1: 11月 | Q1: 12月 | S1: =TODAY() -> 46020
A2: 可研 | B2: 计划评审 | C2: 每月数量 | D2: 广州局 | E2: 每月计划 | F2: =IF($S$1<DATE(2025,1,1)," ",IF((SUM(F3:F9)-MAX(F15,F19))<0,"ERR",SUM(F3:F9))) -> 6 | G2: =IF($S$1<DATE(2025,2,1)," ",IF((SUM(G3:G9)-MAX(G15,G19))<0,"ERR",SUM(G3:G9))) -> 1 | H2: =IF($S$1<DATE(2025,3,1)," ",IF((SUM(H3:H9)-MAX(H15,H19))<0,"ERR",SUM(H3:H9))) -> 4 | I2: =IF($S$1<DATE(2025,4,1)," ",IF((SUM(I3:I9)-MAX(I15,I19))<0,"ERR",SUM(I3:I9))) -> 5 | J2: =IF($S$1<DATE(2025,5,1)," ",IF((SUM(J3:J9)-MAX(J15,J19))<0,"ERR",SUM(J3:J9))) -> 1 | K2: =IF($S$1<DATE(2025,6,1)," ",IF((SUM(K3:K9)-MAX(K15,K19))<0,"ERR",SUM(K3:K9))) -> 5 | L2: =IF($S$1<DATE(2025,7,1)," ",IF((SUM(L3:L9)-MAX(L15,L19))<0,"ERR",SUM(L3:L9))) -> 6 | M2: =IF($S$1<DATE(2025,8,1)," ",IF((SUM(M3:M9)-MAX(M15,M19))<0,"ERR",SUM(M3:M9))) -> 5 | N2: =IF($S$1<DATE(2025,9,1)," ",IF((SUM(N3:N9)-MAX(N15,N19))<0,"ERR",SUM(N3:N9))) -> 5 | O2: =IF($S$1<DATE(2025,10,1)," ",IF((SUM(O3:O9)-MAX(O15,O19))<0,"ERR",SUM(O3:O9))) -> 7 | P2: =IF($S$1<DATE(2025,11,1)," ",IF((SUM(P3:P9)-MAX(P15,P19))<0,"ERR",SUM(P3:P9))) -> 8 | Q2: =IF($S$1<DATE(2025,12,1)," ",IF((SUM(Q3:Q9)-MAX(Q15,Q19))<0,"ERR",SUM(Q3:Q9))) -> 3 | S2: 设计阶段 | T2: 评审阶段 | U2: 统计维度 | V2: 单位 | W2: 统计项目 | X2: 1月 | Y2: 2月 | Z2: 3月 | AA2: 4月 | AB2: 5月 | AC2: 6月 | AD2: 7月 | AE2: 8月 | AF2: 9月 | AG2: 10月 | AH2: 11月 | AI2: 12月
A3: 可研 | B3: 计划评审 | C3: 每月数量 | D3: 负责人 | E3: 方明 | F3: =IF($S$1<DATE(2025,1,1)," ",COUNTIFS('2025数据'!$C$3:$C$181,">="&DATE(2024,1,1),'2025数据'!$C$3:$C$181,"<="&DATE(2025,1,31),'2025数据'!$AE$3:$AE$181,$E3)) -> 0 | G3: =IF($S$1<DATE(2025,2,1)," ",COUNTIFS('2025数据'!$C$3:$C$181,">="&DATE(2025,2,1),'2025数据'!$C$3:$C$181,"<="&DATE(2025,2,28),'2025数据'!$AE$3:$AE$181,$E3)) -> 1 | H3: =IF($S$1<DATE(2025,3,1)," ",COUNTIFS('2025数据'!$C$3:$C$181,">="&DATE(2025,3,1),'2025数据'!$C$3:$C$181,"<="&DATE(2025,3,31),'2025数据'!$AE$3:$AE$181,$E3)) -> 1 | I3: =IF($S$1<DATE(2025,4,1)," ",COUNTIFS('2025数据'!$C$3:$C$181,">="&DATE(2025,4,1),'2025数据'!$C$3:$C$181,"<="&DATE(2025,4,30),'2025数据'!$AE$3:$AE$181,$E3)) -> 3 | J3: =IF($S$1<DATE(2025,5,1)," ",COUNTIFS('2025数据'!$C$3:$C$181,">="&DATE(2025,5,1),'2025数据'!$C$3:$C$181,"<="&DATE(2025,5,31),'2025数据'!$AE$3:$AE$181,$E3)) -> 0 | K3: =IF($S$1<DATE(2025,6,1)," ",COUNTIFS('2025数据'!$C$3:$C$181,">="&DATE(2025,6,1),'2025数据'!$C$3:$C$181,"<="&DATE(2025,6,30),'2025数据'!$AE$3:$AE$181,$E3)) -> 2 | L3: =IF($S$1<DATE(2025,7,1)," ",COUNTIFS('2025数据'!$C$3:$C$181,">="&DATE(2025,7,1),'2025数据'!$C$3:$C$181,"<="&DATE(2025,7,31),'2025数据'!$AE$3:$AE$181,$E3)) -> 1 | M3: =IF($S$1<DATE(2025,8,1)," ",COUNTIFS('2025数据'!$C$3:$C$181,">="&DATE(2025,8,1),'2025数据'!$C$3:$C$181,"<="&DATE(2025,8,31),'2025数据'!$AE$3:$AE$181,$E3)) -> 2 | N3: =IF($S$1<DATE(2025,9,1)," ",COUNTIFS('2025数据'!$C$3:$C$181,">="&DATE(2025,9,1),'2025数据'!$C$3:$C$181,"<="&DATE(2025,9,30),'2025数据'!$AE$3:$AE$181,$E3)) -> 3 | O3: =IF($S$1<DATE(2025,10,1)," ",COUNTIFS('2025数据'!$C$3:$C$181,">="&DATE(2025,10,1),'2025数据'!$C$3:$C$181,"<="&DATE(2025,10,31),'2025数据'!$AE$3:$AE$181,$E3)) -> 0 | P3: =IF($S$1<DATE(2025,11,1)," ",COUNTIFS('2025数据'!$C$3:$C$181,">="&DATE(2025,11,1),'2025数据'!$C$3:$C$181,"<="&DATE(2025,11,30),'2025数据'!$AE$3:$AE$181,$E3)) -> 1 | Q3: =IF($S$1<DATE(2025,12,1)," ",COUNTIFS('2025数据'!$C$3:$C$181,">="&DATE(2025,12,1),'2025数据'!$C$3:$C$181,"<="&DATE(2025,12,31),'2025数据'!$AE$3:$AE$181,$E3)) -> 2
A4: 可研 | B4: 计划评审 | C4: 每月数量 | D4: 负责人 | E4: 谢瑞莲 | F4: =IF($S$1<DATE(2025,1,1)," ",COUNTIFS('2025数据'!$C$3:$C$181,">="&DATE(2024,1,1),'2025数据'!$C$3:$C$181,"<="&DATE(2025,1,31),'2025数据'!$AE$3:$AE$181,$E4)) -> 2 | G4: =IF($S$1<DATE(2025,2,1)," ",COUNTIFS('2025数据'!$C$3:$C$181,">="&DATE(2025,2,1),'2025数据'!$C$3:$C$181,"<="&DATE(2025,2,28),'2025数据'!$AE$3:$AE$181,$E4)) -> 0 | H4: =IF($S$1<DATE(2025,3,1)," ",COUNTIFS('2025数据'!$C$3:$C$181,">="&DATE(2025,3,1),'2025数据'!$C$3:$C$181,"<="&DATE(2025,3,31),'2025数据'!$AE$3:$AE$181,$E4)) -> 3 | I4: =IF($S$1<DATE(2025,4,1)," ",COUNTIFS('2025数据'!$C$3:$C$181,">="&DATE(2025,4,1),'2025数据'!$C$3:$C$181,"<="&DATE(2025,4,30),'2025数据'!$AE$3:$AE$181,$E4)) -> 1 | J4: =IF($S$1<DATE(2025,5,1)," ",COUNTIFS('2025数据'!$C$3:$C$181,">="&DATE(2025,5,1),'2025数据'!$C$3:$C$181,"<="&DATE(2025,5,31),'2025数据'!$AE$3:$AE$181,$E4)) -> 0 | K4: =IF($S$1<DATE(2025,6,1)," ",COUNTIFS('2025数据'!$C$3:$C$181,">="&DATE(2025,6,1),'2025数据'!$C$3:$C$181,"<="&DATE(2025,6,30),'2025数据'!$AE$3:$AE$181,$E4)) -> 1 | L4: =IF($S$1<DATE(2025,7,1)," ",COUNTIFS('2025数据'!$C$3:$C$181,">="&DATE(2025,7,1),'2025数据'!$C$3:$C$181,"<="&DATE(2025,7,31),'2025数据'!$AE$3:$AE$181,$E4)) -> 0 | M4: =IF($S$1<DATE(2025,8,1)," ",COUNTIFS('2025数据'!$C$3:$C$181,">="&DATE(2025,8,1),'2025数据'!$C$3:$C$181,"<="&DATE(2025,8,31),'2025数据'!$AE$3:$AE$181,$E4)) -> 1 | N4: =IF($S$1<DATE(2025,9,1)," ",COUNTIFS('2025数据'!$C$3:$C$181,">="&DATE(2025,9,1),'2025数据'!$C$3:$C$181,"<="&DATE(2025,9,30),'2025数据'!$AE$3:$AE$181,$E4)) -> 0 | O4: =IF($S$1<DATE(2025,10,1)," ",COUNTIFS('2025数据'!$C$3:$C$181,">="&DATE(2025,10,1),'2025数据'!$C$3:$C$181,"<="&DATE(2025,10,31),'2025数据'!$AE$3:$AE$181,$E4)) -> 5 | P4: =IF($S$1<DATE(2025,11,1)," ",COUNTIFS('2025数据'!$C$3:$C$181,">="&DATE(2025,11,1),'2025数据'!$C$3:$C$181,"<="&DATE(2025,11,30),'2025数据'!$AE$3:$AE$181,$E4)) -> 1 | Q4: =IF($S$1<DATE(2025,12,1)," ",COUNTIFS('2025数据'!$C$3:$C$181,">="&DATE(2025,12,1),'2025数据'!$C$3:$C$181,"<="&DATE(2025,12,31),'2025数据'!$AE$3:$AE$181,$E4)) -> 1
